[2022-05-22 01:13:13,130] {taskinstance.py:1159} INFO - Dependencies all met for <TaskInstance: Teste_ETL_Raízen.extract_tables_file scheduled__2022-05-21T23:30:00+00:00 [queued]>
[2022-05-22 01:13:13,139] {taskinstance.py:1159} INFO - Dependencies all met for <TaskInstance: Teste_ETL_Raízen.extract_tables_file scheduled__2022-05-21T23:30:00+00:00 [queued]>
[2022-05-22 01:13:13,139] {taskinstance.py:1356} INFO - 
--------------------------------------------------------------------------------
[2022-05-22 01:13:13,139] {taskinstance.py:1357} INFO - Starting attempt 1 of 1
[2022-05-22 01:13:13,139] {taskinstance.py:1358} INFO - 
--------------------------------------------------------------------------------
[2022-05-22 01:13:13,152] {taskinstance.py:1377} INFO - Executing <Task(PythonOperator): extract_tables_file> on 2022-05-21 23:30:00+00:00
[2022-05-22 01:13:13,157] {standard_task_runner.py:52} INFO - Started process 356 to run task
[2022-05-22 01:13:13,159] {standard_task_runner.py:79} INFO - Running: ['***', 'tasks', 'run', 'Teste_ETL_Raízen', 'extract_tables_file', 'scheduled__2022-05-21T23:30:00+00:00', '--job-id', '20', '--raw', '--subdir', 'DAGS_FOLDER/ETL_Raizen.py', '--cfg-path', '/tmp/tmpqn60yfk1', '--error-file', '/tmp/tmpqcb4kd3r']
[2022-05-22 01:13:13,160] {standard_task_runner.py:80} INFO - Job 20: Subtask extract_tables_file
[2022-05-22 01:13:13,202] {task_command.py:369} INFO - Running <TaskInstance: Teste_ETL_Raízen.extract_tables_file scheduled__2022-05-21T23:30:00+00:00 [running]> on host 0a31d31582dc
[2022-05-22 01:13:13,267] {taskinstance.py:1571} INFO - Exporting the following env vars:
AIRFLOW_CTX_DAG_OWNER=***
AIRFLOW_CTX_DAG_ID=Teste_ETL_Raízen
AIRFLOW_CTX_TASK_ID=extract_tables_file
AIRFLOW_CTX_EXECUTION_DATE=2022-05-21T23:30:00+00:00
AIRFLOW_CTX_TRY_NUMBER=1
AIRFLOW_CTX_DAG_RUN_ID=scheduled__2022-05-21T23:30:00+00:00
[2022-05-22 01:13:13,269] {taskinstance.py:1889} ERROR - Task failed with exception
Traceback (most recent call last):
  File "/home/airflow/.local/lib/python3.7/site-packages/airflow/operators/python.py", line 171, in execute
    return_value = self.execute_callable()
  File "/home/airflow/.local/lib/python3.7/site-packages/airflow/operators/python.py", line 189, in execute_callable
    return self.python_callable(*self.op_args, **self.op_kwargs)
  File "/opt/airflow/dags/ETL_Raizen.py", line 39, in extract_tables_file
    extract_xlsx_sheet(path, i , f"{sheets[i]}.xlsx")
  File "/opt/airflow/dags/ETL_Raizen.py", line 28, in extract_xlsx_sheet
    wb = load_workbook(file_location)
  File "/home/airflow/.local/lib/python3.7/site-packages/openpyxl/reader/excel.py", line 316, in load_workbook
    data_only, keep_links)
  File "/home/airflow/.local/lib/python3.7/site-packages/openpyxl/reader/excel.py", line 124, in __init__
    self.archive = _validate_archive(fn)
  File "/home/airflow/.local/lib/python3.7/site-packages/openpyxl/reader/excel.py", line 96, in _validate_archive
    archive = ZipFile(filename, 'r')
  File "/usr/local/lib/python3.7/zipfile.py", line 1240, in __init__
    self.fp = io.open(file, filemode)
FileNotFoundError: [Errno 2] No such file or directory: '/home/netomadazio/workspace/desafio_raizen/raw_data/vendas-combustiveis-m3.xlsx'
[2022-05-22 01:13:13,277] {taskinstance.py:1400} INFO - Marking task as FAILED. dag_id=Teste_ETL_Raízen, task_id=extract_tables_file, execution_date=20220521T233000, start_date=20220522T011313, end_date=20220522T011313
[2022-05-22 01:13:13,287] {standard_task_runner.py:97} ERROR - Failed to execute job 20 for task extract_tables_file ([Errno 2] No such file or directory: '/home/netomadazio/workspace/desafio_raizen/raw_data/vendas-combustiveis-m3.xlsx'; 356)
[2022-05-22 01:13:13,332] {local_task_job.py:156} INFO - Task exited with return code 1
[2022-05-22 01:13:13,407] {local_task_job.py:273} INFO - 0 downstream tasks scheduled from follow-on schedule check
