[2022-05-22 01:13:24,435] {taskinstance.py:1159} INFO - Dependencies all met for <TaskInstance: Teste_ETL_Raízen.extract_tables_file manual__2022-05-22T01:13:21.300089+00:00 [queued]>
[2022-05-22 01:13:24,448] {taskinstance.py:1159} INFO - Dependencies all met for <TaskInstance: Teste_ETL_Raízen.extract_tables_file manual__2022-05-22T01:13:21.300089+00:00 [queued]>
[2022-05-22 01:13:24,448] {taskinstance.py:1356} INFO - 
--------------------------------------------------------------------------------
[2022-05-22 01:13:24,448] {taskinstance.py:1357} INFO - Starting attempt 1 of 1
[2022-05-22 01:13:24,448] {taskinstance.py:1358} INFO - 
--------------------------------------------------------------------------------
[2022-05-22 01:13:24,468] {taskinstance.py:1377} INFO - Executing <Task(PythonOperator): extract_tables_file> on 2022-05-22 01:13:21.300089+00:00
[2022-05-22 01:13:24,473] {standard_task_runner.py:52} INFO - Started process 411 to run task
[2022-05-22 01:13:24,476] {standard_task_runner.py:79} INFO - Running: ['***', 'tasks', 'run', 'Teste_ETL_Raízen', 'extract_tables_file', 'manual__2022-05-22T01:13:21.300089+00:00', '--job-id', '22', '--raw', '--subdir', 'DAGS_FOLDER/ETL_Raizen.py', '--cfg-path', '/tmp/tmp5x336g89', '--error-file', '/tmp/tmpu075i7i7']
[2022-05-22 01:13:24,477] {standard_task_runner.py:80} INFO - Job 22: Subtask extract_tables_file
[2022-05-22 01:13:24,523] {task_command.py:369} INFO - Running <TaskInstance: Teste_ETL_Raízen.extract_tables_file manual__2022-05-22T01:13:21.300089+00:00 [running]> on host 0a31d31582dc
[2022-05-22 01:13:24,589] {taskinstance.py:1571} INFO - Exporting the following env vars:
AIRFLOW_CTX_DAG_OWNER=***
AIRFLOW_CTX_DAG_ID=Teste_ETL_Raízen
AIRFLOW_CTX_TASK_ID=extract_tables_file
AIRFLOW_CTX_EXECUTION_DATE=2022-05-22T01:13:21.300089+00:00
AIRFLOW_CTX_TRY_NUMBER=1
AIRFLOW_CTX_DAG_RUN_ID=manual__2022-05-22T01:13:21.300089+00:00
[2022-05-22 01:13:24,590] {taskinstance.py:1889} ERROR - Task failed with exception
Traceback (most recent call last):
  File "/home/airflow/.local/lib/python3.7/site-packages/airflow/operators/python.py", line 171, in execute
    return_value = self.execute_callable()
  File "/home/airflow/.local/lib/python3.7/site-packages/airflow/operators/python.py", line 189, in execute_callable
    return self.python_callable(*self.op_args, **self.op_kwargs)
  File "/opt/airflow/dags/ETL_Raizen.py", line 39, in extract_tables_file
    extract_xlsx_sheet(path, i , f"{sheets[i]}.xlsx")
  File "/opt/airflow/dags/ETL_Raizen.py", line 28, in extract_xlsx_sheet
    wb = load_workbook(file_location)
  File "/home/airflow/.local/lib/python3.7/site-packages/openpyxl/reader/excel.py", line 316, in load_workbook
    data_only, keep_links)
  File "/home/airflow/.local/lib/python3.7/site-packages/openpyxl/reader/excel.py", line 124, in __init__
    self.archive = _validate_archive(fn)
  File "/home/airflow/.local/lib/python3.7/site-packages/openpyxl/reader/excel.py", line 96, in _validate_archive
    archive = ZipFile(filename, 'r')
  File "/usr/local/lib/python3.7/zipfile.py", line 1240, in __init__
    self.fp = io.open(file, filemode)
FileNotFoundError: [Errno 2] No such file or directory: '/home/netomadazio/workspace/desafio_raizen/raw_data/vendas-combustiveis-m3.xlsx'
[2022-05-22 01:13:24,598] {taskinstance.py:1400} INFO - Marking task as FAILED. dag_id=Teste_ETL_Raízen, task_id=extract_tables_file, execution_date=20220522T011321, start_date=20220522T011324, end_date=20220522T011324
[2022-05-22 01:13:24,608] {standard_task_runner.py:97} ERROR - Failed to execute job 22 for task extract_tables_file ([Errno 2] No such file or directory: '/home/netomadazio/workspace/desafio_raizen/raw_data/vendas-combustiveis-m3.xlsx'; 411)
[2022-05-22 01:13:24,648] {local_task_job.py:156} INFO - Task exited with return code 1
[2022-05-22 01:13:24,690] {local_task_job.py:273} INFO - 0 downstream tasks scheduled from follow-on schedule check
