[2022-05-20 19:03:32,967] {processor.py:153} INFO - Started process (PID=46) to work on /opt/airflow/dags/ETL_Raizen.py
[2022-05-20 19:03:32,967] {processor.py:641} INFO - Processing file /opt/airflow/dags/ETL_Raizen.py for tasks to queue
[2022-05-20 19:03:32,970] {logging_mixin.py:115} INFO - [2022-05-20 19:03:32,969] {dagbag.py:507} INFO - Filling up the DagBag from /opt/airflow/dags/ETL_Raizen.py
[2022-05-20 19:03:34,077] {logging_mixin.py:115} INFO - [2022-05-20 19:03:34,076] {dagbag.py:320} ERROR - Failed to import: /opt/airflow/dags/ETL_Raizen.py
Traceback (most recent call last):
  File "/home/airflow/.local/lib/python3.7/site-packages/airflow/models/dagbag.py", line 317, in parse
    loader.exec_module(new_module)
  File "<frozen importlib._bootstrap_external>", line 728, in exec_module
  File "<frozen importlib._bootstrap>", line 219, in _call_with_frames_removed
  File "/opt/airflow/dags/ETL_Raizen.py", line 107, in <module>
    with DAG('Teste_ETL_Raízen', start_date = datetime(2022,5,18),
NameError: name 'datetime' is not defined
[2022-05-20 19:03:34,077] {processor.py:653} WARNING - No viable dags retrieved from /opt/airflow/dags/ETL_Raizen.py
[2022-05-20 19:03:34,097] {processor.py:161} INFO - Processing /opt/airflow/dags/ETL_Raizen.py took 1.135 seconds
[2022-05-20 19:04:04,478] {processor.py:153} INFO - Started process (PID=111) to work on /opt/airflow/dags/ETL_Raizen.py
[2022-05-20 19:04:04,478] {processor.py:641} INFO - Processing file /opt/airflow/dags/ETL_Raizen.py for tasks to queue
[2022-05-20 19:04:04,479] {logging_mixin.py:115} INFO - [2022-05-20 19:04:04,479] {dagbag.py:507} INFO - Filling up the DagBag from /opt/airflow/dags/ETL_Raizen.py
[2022-05-20 19:04:05,047] {logging_mixin.py:115} INFO - [2022-05-20 19:04:05,046] {dagbag.py:320} ERROR - Failed to import: /opt/airflow/dags/ETL_Raizen.py
Traceback (most recent call last):
  File "/home/airflow/.local/lib/python3.7/site-packages/airflow/models/dagbag.py", line 317, in parse
    loader.exec_module(new_module)
  File "<frozen importlib._bootstrap_external>", line 728, in exec_module
  File "<frozen importlib._bootstrap>", line 219, in _call_with_frames_removed
  File "/opt/airflow/dags/ETL_Raizen.py", line 107, in <module>
    with DAG('Teste_ETL_Raízen', start_date = datetime(2022,5,18),
NameError: name 'datetime' is not defined
[2022-05-20 19:04:05,047] {processor.py:653} WARNING - No viable dags retrieved from /opt/airflow/dags/ETL_Raizen.py
[2022-05-20 19:04:05,068] {processor.py:161} INFO - Processing /opt/airflow/dags/ETL_Raizen.py took 0.593 seconds
[2022-05-20 19:04:35,323] {processor.py:153} INFO - Started process (PID=167) to work on /opt/airflow/dags/ETL_Raizen.py
[2022-05-20 19:04:35,324] {processor.py:641} INFO - Processing file /opt/airflow/dags/ETL_Raizen.py for tasks to queue
[2022-05-20 19:04:35,324] {logging_mixin.py:115} INFO - [2022-05-20 19:04:35,324] {dagbag.py:507} INFO - Filling up the DagBag from /opt/airflow/dags/ETL_Raizen.py
[2022-05-20 19:04:35,736] {logging_mixin.py:115} INFO - [2022-05-20 19:04:35,735] {dagbag.py:320} ERROR - Failed to import: /opt/airflow/dags/ETL_Raizen.py
Traceback (most recent call last):
  File "/home/airflow/.local/lib/python3.7/site-packages/airflow/models/dagbag.py", line 317, in parse
    loader.exec_module(new_module)
  File "<frozen importlib._bootstrap_external>", line 728, in exec_module
  File "<frozen importlib._bootstrap>", line 219, in _call_with_frames_removed
  File "/opt/airflow/dags/ETL_Raizen.py", line 107, in <module>
    with DAG('Teste_ETL_Raízen', start_date = datetime(2022,5,18),
NameError: name 'datetime' is not defined
[2022-05-20 19:04:35,736] {processor.py:653} WARNING - No viable dags retrieved from /opt/airflow/dags/ETL_Raizen.py
[2022-05-20 19:04:35,751] {processor.py:161} INFO - Processing /opt/airflow/dags/ETL_Raizen.py took 0.430 seconds
[2022-05-20 19:05:05,916] {processor.py:153} INFO - Started process (PID=232) to work on /opt/airflow/dags/ETL_Raizen.py
[2022-05-20 19:05:05,925] {processor.py:641} INFO - Processing file /opt/airflow/dags/ETL_Raizen.py for tasks to queue
[2022-05-20 19:05:05,926] {logging_mixin.py:115} INFO - [2022-05-20 19:05:05,926] {dagbag.py:507} INFO - Filling up the DagBag from /opt/airflow/dags/ETL_Raizen.py
[2022-05-20 19:05:06,282] {logging_mixin.py:115} INFO - [2022-05-20 19:05:06,281] {dagbag.py:320} ERROR - Failed to import: /opt/airflow/dags/ETL_Raizen.py
Traceback (most recent call last):
  File "/home/airflow/.local/lib/python3.7/site-packages/airflow/models/dagbag.py", line 317, in parse
    loader.exec_module(new_module)
  File "<frozen importlib._bootstrap_external>", line 728, in exec_module
  File "<frozen importlib._bootstrap>", line 219, in _call_with_frames_removed
  File "/opt/airflow/dags/ETL_Raizen.py", line 107, in <module>
    with DAG('Teste_ETL_Raízen', start_date = datetime(2022,5,18),
NameError: name 'datetime' is not defined
[2022-05-20 19:05:06,282] {processor.py:653} WARNING - No viable dags retrieved from /opt/airflow/dags/ETL_Raizen.py
[2022-05-20 19:05:06,296] {processor.py:161} INFO - Processing /opt/airflow/dags/ETL_Raizen.py took 0.387 seconds
[2022-05-20 19:05:37,287] {processor.py:153} INFO - Started process (PID=296) to work on /opt/airflow/dags/ETL_Raizen.py
[2022-05-20 19:05:37,288] {processor.py:641} INFO - Processing file /opt/airflow/dags/ETL_Raizen.py for tasks to queue
[2022-05-20 19:05:37,289] {logging_mixin.py:115} INFO - [2022-05-20 19:05:37,289] {dagbag.py:507} INFO - Filling up the DagBag from /opt/airflow/dags/ETL_Raizen.py
[2022-05-20 19:05:37,654] {logging_mixin.py:115} INFO - [2022-05-20 19:05:37,654] {dagbag.py:320} ERROR - Failed to import: /opt/airflow/dags/ETL_Raizen.py
Traceback (most recent call last):
  File "/home/airflow/.local/lib/python3.7/site-packages/airflow/models/dagbag.py", line 317, in parse
    loader.exec_module(new_module)
  File "<frozen importlib._bootstrap_external>", line 728, in exec_module
  File "<frozen importlib._bootstrap>", line 219, in _call_with_frames_removed
  File "/opt/airflow/dags/ETL_Raizen.py", line 107, in <module>
    with DAG('Teste_ETL_Raízen', start_date = datetime(2022,5,18),
NameError: name 'datetime' is not defined
[2022-05-20 19:05:37,654] {processor.py:653} WARNING - No viable dags retrieved from /opt/airflow/dags/ETL_Raizen.py
[2022-05-20 19:05:37,670] {processor.py:161} INFO - Processing /opt/airflow/dags/ETL_Raizen.py took 0.391 seconds
[2022-05-20 19:06:07,919] {processor.py:153} INFO - Started process (PID=352) to work on /opt/airflow/dags/ETL_Raizen.py
[2022-05-20 19:06:07,919] {processor.py:641} INFO - Processing file /opt/airflow/dags/ETL_Raizen.py for tasks to queue
[2022-05-20 19:06:07,920] {logging_mixin.py:115} INFO - [2022-05-20 19:06:07,920] {dagbag.py:507} INFO - Filling up the DagBag from /opt/airflow/dags/ETL_Raizen.py
[2022-05-20 19:06:08,256] {logging_mixin.py:115} INFO - [2022-05-20 19:06:08,256] {dagbag.py:320} ERROR - Failed to import: /opt/airflow/dags/ETL_Raizen.py
Traceback (most recent call last):
  File "/home/airflow/.local/lib/python3.7/site-packages/airflow/models/dagbag.py", line 317, in parse
    loader.exec_module(new_module)
  File "<frozen importlib._bootstrap_external>", line 728, in exec_module
  File "<frozen importlib._bootstrap>", line 219, in _call_with_frames_removed
  File "/opt/airflow/dags/ETL_Raizen.py", line 107, in <module>
    with DAG('Teste_ETL_Raízen', start_date = datetime(2022,5,18),
NameError: name 'datetime' is not defined
[2022-05-20 19:06:08,257] {processor.py:653} WARNING - No viable dags retrieved from /opt/airflow/dags/ETL_Raizen.py
[2022-05-20 19:06:08,271] {processor.py:161} INFO - Processing /opt/airflow/dags/ETL_Raizen.py took 0.354 seconds
[2022-05-20 19:06:38,327] {processor.py:153} INFO - Started process (PID=417) to work on /opt/airflow/dags/ETL_Raizen.py
[2022-05-20 19:06:38,335] {processor.py:641} INFO - Processing file /opt/airflow/dags/ETL_Raizen.py for tasks to queue
[2022-05-20 19:06:38,336] {logging_mixin.py:115} INFO - [2022-05-20 19:06:38,336] {dagbag.py:507} INFO - Filling up the DagBag from /opt/airflow/dags/ETL_Raizen.py
[2022-05-20 19:06:38,679] {logging_mixin.py:115} INFO - [2022-05-20 19:06:38,679] {dagbag.py:320} ERROR - Failed to import: /opt/airflow/dags/ETL_Raizen.py
Traceback (most recent call last):
  File "/home/airflow/.local/lib/python3.7/site-packages/airflow/models/dagbag.py", line 317, in parse
    loader.exec_module(new_module)
  File "<frozen importlib._bootstrap_external>", line 728, in exec_module
  File "<frozen importlib._bootstrap>", line 219, in _call_with_frames_removed
  File "/opt/airflow/dags/ETL_Raizen.py", line 107, in <module>
    with DAG('Teste_ETL_Raízen', start_date = datetime(2022,5,18),
NameError: name 'datetime' is not defined
[2022-05-20 19:06:38,679] {processor.py:653} WARNING - No viable dags retrieved from /opt/airflow/dags/ETL_Raizen.py
[2022-05-20 19:06:38,700] {processor.py:161} INFO - Processing /opt/airflow/dags/ETL_Raizen.py took 0.376 seconds
[2022-05-20 19:07:08,903] {processor.py:153} INFO - Started process (PID=481) to work on /opt/airflow/dags/ETL_Raizen.py
[2022-05-20 19:07:08,904] {processor.py:641} INFO - Processing file /opt/airflow/dags/ETL_Raizen.py for tasks to queue
[2022-05-20 19:07:08,905] {logging_mixin.py:115} INFO - [2022-05-20 19:07:08,904] {dagbag.py:507} INFO - Filling up the DagBag from /opt/airflow/dags/ETL_Raizen.py
[2022-05-20 19:07:09,238] {logging_mixin.py:115} INFO - [2022-05-20 19:07:09,238] {dagbag.py:320} ERROR - Failed to import: /opt/airflow/dags/ETL_Raizen.py
Traceback (most recent call last):
  File "/home/airflow/.local/lib/python3.7/site-packages/airflow/models/dagbag.py", line 317, in parse
    loader.exec_module(new_module)
  File "<frozen importlib._bootstrap_external>", line 728, in exec_module
  File "<frozen importlib._bootstrap>", line 219, in _call_with_frames_removed
  File "/opt/airflow/dags/ETL_Raizen.py", line 107, in <module>
    with DAG('Teste_ETL_Raízen', start_date = datetime(2022,5,18),
NameError: name 'datetime' is not defined
[2022-05-20 19:07:09,239] {processor.py:653} WARNING - No viable dags retrieved from /opt/airflow/dags/ETL_Raizen.py
[2022-05-20 19:07:09,252] {processor.py:161} INFO - Processing /opt/airflow/dags/ETL_Raizen.py took 0.351 seconds
[2022-05-20 19:07:39,293] {processor.py:153} INFO - Started process (PID=537) to work on /opt/airflow/dags/ETL_Raizen.py
[2022-05-20 19:07:39,301] {processor.py:641} INFO - Processing file /opt/airflow/dags/ETL_Raizen.py for tasks to queue
[2022-05-20 19:07:39,302] {logging_mixin.py:115} INFO - [2022-05-20 19:07:39,301] {dagbag.py:507} INFO - Filling up the DagBag from /opt/airflow/dags/ETL_Raizen.py
[2022-05-20 19:07:39,639] {logging_mixin.py:115} INFO - [2022-05-20 19:07:39,638] {dagbag.py:320} ERROR - Failed to import: /opt/airflow/dags/ETL_Raizen.py
Traceback (most recent call last):
  File "/home/airflow/.local/lib/python3.7/site-packages/airflow/models/dagbag.py", line 317, in parse
    loader.exec_module(new_module)
  File "<frozen importlib._bootstrap_external>", line 728, in exec_module
  File "<frozen importlib._bootstrap>", line 219, in _call_with_frames_removed
  File "/opt/airflow/dags/ETL_Raizen.py", line 107, in <module>
    with DAG('Teste_ETL_Raízen', start_date = datetime(2022,5,18),
NameError: name 'datetime' is not defined
[2022-05-20 19:07:39,639] {processor.py:653} WARNING - No viable dags retrieved from /opt/airflow/dags/ETL_Raizen.py
[2022-05-20 19:07:39,653] {processor.py:161} INFO - Processing /opt/airflow/dags/ETL_Raizen.py took 0.363 seconds
[2022-05-20 19:08:09,883] {processor.py:153} INFO - Started process (PID=602) to work on /opt/airflow/dags/ETL_Raizen.py
[2022-05-20 19:08:09,891] {processor.py:641} INFO - Processing file /opt/airflow/dags/ETL_Raizen.py for tasks to queue
[2022-05-20 19:08:09,893] {logging_mixin.py:115} INFO - [2022-05-20 19:08:09,893] {dagbag.py:507} INFO - Filling up the DagBag from /opt/airflow/dags/ETL_Raizen.py
[2022-05-20 19:08:10,204] {logging_mixin.py:115} INFO - [2022-05-20 19:08:10,203] {dagbag.py:320} ERROR - Failed to import: /opt/airflow/dags/ETL_Raizen.py
Traceback (most recent call last):
  File "/home/airflow/.local/lib/python3.7/site-packages/airflow/models/dagbag.py", line 317, in parse
    loader.exec_module(new_module)
  File "<frozen importlib._bootstrap_external>", line 728, in exec_module
  File "<frozen importlib._bootstrap>", line 219, in _call_with_frames_removed
  File "/opt/airflow/dags/ETL_Raizen.py", line 107, in <module>
    with DAG('Teste_ETL_Raízen', start_date = datetime(2022,5,18),
NameError: name 'datetime' is not defined
[2022-05-20 19:08:10,204] {processor.py:653} WARNING - No viable dags retrieved from /opt/airflow/dags/ETL_Raizen.py
[2022-05-20 19:08:10,225] {processor.py:161} INFO - Processing /opt/airflow/dags/ETL_Raizen.py took 0.344 seconds
[2022-05-20 19:08:40,302] {processor.py:153} INFO - Started process (PID=668) to work on /opt/airflow/dags/ETL_Raizen.py
[2022-05-20 19:08:40,303] {processor.py:641} INFO - Processing file /opt/airflow/dags/ETL_Raizen.py for tasks to queue
[2022-05-20 19:08:40,303] {logging_mixin.py:115} INFO - [2022-05-20 19:08:40,303] {dagbag.py:507} INFO - Filling up the DagBag from /opt/airflow/dags/ETL_Raizen.py
[2022-05-20 19:08:40,635] {logging_mixin.py:115} INFO - [2022-05-20 19:08:40,634] {dagbag.py:320} ERROR - Failed to import: /opt/airflow/dags/ETL_Raizen.py
Traceback (most recent call last):
  File "/home/airflow/.local/lib/python3.7/site-packages/airflow/models/dagbag.py", line 317, in parse
    loader.exec_module(new_module)
  File "<frozen importlib._bootstrap_external>", line 728, in exec_module
  File "<frozen importlib._bootstrap>", line 219, in _call_with_frames_removed
  File "/opt/airflow/dags/ETL_Raizen.py", line 107, in <module>
    with DAG('Teste_ETL_Raízen', start_date = datetime(2022,5,18),
NameError: name 'datetime' is not defined
[2022-05-20 19:08:40,635] {processor.py:653} WARNING - No viable dags retrieved from /opt/airflow/dags/ETL_Raizen.py
[2022-05-20 19:08:40,649] {processor.py:161} INFO - Processing /opt/airflow/dags/ETL_Raizen.py took 0.348 seconds
[2022-05-20 19:09:11,482] {processor.py:153} INFO - Started process (PID=724) to work on /opt/airflow/dags/ETL_Raizen.py
[2022-05-20 19:09:11,483] {processor.py:641} INFO - Processing file /opt/airflow/dags/ETL_Raizen.py for tasks to queue
[2022-05-20 19:09:11,483] {logging_mixin.py:115} INFO - [2022-05-20 19:09:11,483] {dagbag.py:507} INFO - Filling up the DagBag from /opt/airflow/dags/ETL_Raizen.py
[2022-05-20 19:09:11,808] {logging_mixin.py:115} INFO - [2022-05-20 19:09:11,808] {dagbag.py:320} ERROR - Failed to import: /opt/airflow/dags/ETL_Raizen.py
Traceback (most recent call last):
  File "/home/airflow/.local/lib/python3.7/site-packages/airflow/models/dagbag.py", line 317, in parse
    loader.exec_module(new_module)
  File "<frozen importlib._bootstrap_external>", line 728, in exec_module
  File "<frozen importlib._bootstrap>", line 219, in _call_with_frames_removed
  File "/opt/airflow/dags/ETL_Raizen.py", line 107, in <module>
    with DAG('Teste_ETL_Raízen', start_date = datetime(2022,5,18),
NameError: name 'datetime' is not defined
[2022-05-20 19:09:11,809] {processor.py:653} WARNING - No viable dags retrieved from /opt/airflow/dags/ETL_Raizen.py
[2022-05-20 19:09:11,825] {processor.py:161} INFO - Processing /opt/airflow/dags/ETL_Raizen.py took 0.345 seconds
[2022-05-20 19:09:42,240] {processor.py:153} INFO - Started process (PID=789) to work on /opt/airflow/dags/ETL_Raizen.py
[2022-05-20 19:09:42,249] {processor.py:641} INFO - Processing file /opt/airflow/dags/ETL_Raizen.py for tasks to queue
[2022-05-20 19:09:42,249] {logging_mixin.py:115} INFO - [2022-05-20 19:09:42,249] {dagbag.py:507} INFO - Filling up the DagBag from /opt/airflow/dags/ETL_Raizen.py
[2022-05-20 19:09:42,587] {logging_mixin.py:115} INFO - [2022-05-20 19:09:42,586] {dagbag.py:320} ERROR - Failed to import: /opt/airflow/dags/ETL_Raizen.py
Traceback (most recent call last):
  File "/home/airflow/.local/lib/python3.7/site-packages/airflow/models/dagbag.py", line 317, in parse
    loader.exec_module(new_module)
  File "<frozen importlib._bootstrap_external>", line 728, in exec_module
  File "<frozen importlib._bootstrap>", line 219, in _call_with_frames_removed
  File "/opt/airflow/dags/ETL_Raizen.py", line 107, in <module>
    with DAG('Teste_ETL_Raízen', start_date = datetime(2022,5,18),
NameError: name 'datetime' is not defined
[2022-05-20 19:09:42,587] {processor.py:653} WARNING - No viable dags retrieved from /opt/airflow/dags/ETL_Raizen.py
[2022-05-20 19:09:42,610] {processor.py:161} INFO - Processing /opt/airflow/dags/ETL_Raizen.py took 0.373 seconds
[2022-05-20 19:10:12,986] {processor.py:153} INFO - Started process (PID=854) to work on /opt/airflow/dags/ETL_Raizen.py
[2022-05-20 19:10:12,994] {processor.py:641} INFO - Processing file /opt/airflow/dags/ETL_Raizen.py for tasks to queue
[2022-05-20 19:10:12,995] {logging_mixin.py:115} INFO - [2022-05-20 19:10:12,995] {dagbag.py:507} INFO - Filling up the DagBag from /opt/airflow/dags/ETL_Raizen.py
[2022-05-20 19:10:13,331] {logging_mixin.py:115} INFO - [2022-05-20 19:10:13,331] {dagbag.py:320} ERROR - Failed to import: /opt/airflow/dags/ETL_Raizen.py
Traceback (most recent call last):
  File "/home/airflow/.local/lib/python3.7/site-packages/airflow/models/dagbag.py", line 317, in parse
    loader.exec_module(new_module)
  File "<frozen importlib._bootstrap_external>", line 728, in exec_module
  File "<frozen importlib._bootstrap>", line 219, in _call_with_frames_removed
  File "/opt/airflow/dags/ETL_Raizen.py", line 107, in <module>
    with DAG('Teste_ETL_Raízen', start_date = datetime(2022,5,18),
NameError: name 'datetime' is not defined
[2022-05-20 19:10:13,332] {processor.py:653} WARNING - No viable dags retrieved from /opt/airflow/dags/ETL_Raizen.py
[2022-05-20 19:10:13,353] {processor.py:161} INFO - Processing /opt/airflow/dags/ETL_Raizen.py took 0.370 seconds
[2022-05-20 19:10:43,897] {processor.py:153} INFO - Started process (PID=919) to work on /opt/airflow/dags/ETL_Raizen.py
[2022-05-20 19:10:43,905] {processor.py:641} INFO - Processing file /opt/airflow/dags/ETL_Raizen.py for tasks to queue
[2022-05-20 19:10:43,905] {logging_mixin.py:115} INFO - [2022-05-20 19:10:43,905] {dagbag.py:507} INFO - Filling up the DagBag from /opt/airflow/dags/ETL_Raizen.py
[2022-05-20 19:10:44,447] {logging_mixin.py:115} INFO - [2022-05-20 19:10:44,446] {dagbag.py:320} ERROR - Failed to import: /opt/airflow/dags/ETL_Raizen.py
Traceback (most recent call last):
  File "/home/airflow/.local/lib/python3.7/site-packages/airflow/models/dagbag.py", line 317, in parse
    loader.exec_module(new_module)
  File "<frozen importlib._bootstrap_external>", line 728, in exec_module
  File "<frozen importlib._bootstrap>", line 219, in _call_with_frames_removed
  File "/opt/airflow/dags/ETL_Raizen.py", line 107, in <module>
    with DAG('Teste_ETL_Raízen', start_date = datetime(2022,5,18),
NameError: name 'datetime' is not defined
[2022-05-20 19:10:44,447] {processor.py:653} WARNING - No viable dags retrieved from /opt/airflow/dags/ETL_Raizen.py
[2022-05-20 19:10:44,473] {processor.py:161} INFO - Processing /opt/airflow/dags/ETL_Raizen.py took 0.579 seconds
[2022-05-20 19:11:15,290] {processor.py:153} INFO - Started process (PID=975) to work on /opt/airflow/dags/ETL_Raizen.py
[2022-05-20 19:11:15,297] {processor.py:641} INFO - Processing file /opt/airflow/dags/ETL_Raizen.py for tasks to queue
[2022-05-20 19:11:15,298] {logging_mixin.py:115} INFO - [2022-05-20 19:11:15,298] {dagbag.py:507} INFO - Filling up the DagBag from /opt/airflow/dags/ETL_Raizen.py
[2022-05-20 19:11:15,695] {logging_mixin.py:115} INFO - [2022-05-20 19:11:15,694] {dagbag.py:320} ERROR - Failed to import: /opt/airflow/dags/ETL_Raizen.py
Traceback (most recent call last):
  File "/home/airflow/.local/lib/python3.7/site-packages/airflow/models/dagbag.py", line 317, in parse
    loader.exec_module(new_module)
  File "<frozen importlib._bootstrap_external>", line 728, in exec_module
  File "<frozen importlib._bootstrap>", line 219, in _call_with_frames_removed
  File "/opt/airflow/dags/ETL_Raizen.py", line 107, in <module>
    with DAG('Teste_ETL_Raízen', start_date = datetime(2022,5,18),
NameError: name 'datetime' is not defined
[2022-05-20 19:11:15,695] {processor.py:653} WARNING - No viable dags retrieved from /opt/airflow/dags/ETL_Raizen.py
[2022-05-20 19:11:15,709] {processor.py:161} INFO - Processing /opt/airflow/dags/ETL_Raizen.py took 0.423 seconds
[2022-05-20 19:11:45,756] {processor.py:153} INFO - Started process (PID=1040) to work on /opt/airflow/dags/ETL_Raizen.py
[2022-05-20 19:11:45,764] {processor.py:641} INFO - Processing file /opt/airflow/dags/ETL_Raizen.py for tasks to queue
[2022-05-20 19:11:45,764] {logging_mixin.py:115} INFO - [2022-05-20 19:11:45,764] {dagbag.py:507} INFO - Filling up the DagBag from /opt/airflow/dags/ETL_Raizen.py
[2022-05-20 19:11:46,090] {logging_mixin.py:115} INFO - [2022-05-20 19:11:46,089] {dagbag.py:320} ERROR - Failed to import: /opt/airflow/dags/ETL_Raizen.py
Traceback (most recent call last):
  File "/home/airflow/.local/lib/python3.7/site-packages/airflow/models/dagbag.py", line 317, in parse
    loader.exec_module(new_module)
  File "<frozen importlib._bootstrap_external>", line 728, in exec_module
  File "<frozen importlib._bootstrap>", line 219, in _call_with_frames_removed
  File "/opt/airflow/dags/ETL_Raizen.py", line 107, in <module>
    with DAG('Teste_ETL_Raízen', start_date = datetime(2022,5,18),
NameError: name 'datetime' is not defined
[2022-05-20 19:11:46,090] {processor.py:653} WARNING - No viable dags retrieved from /opt/airflow/dags/ETL_Raizen.py
[2022-05-20 19:11:46,105] {processor.py:161} INFO - Processing /opt/airflow/dags/ETL_Raizen.py took 0.352 seconds
[2022-05-20 19:12:16,205] {processor.py:153} INFO - Started process (PID=1105) to work on /opt/airflow/dags/ETL_Raizen.py
[2022-05-20 19:12:16,214] {processor.py:641} INFO - Processing file /opt/airflow/dags/ETL_Raizen.py for tasks to queue
[2022-05-20 19:12:16,215] {logging_mixin.py:115} INFO - [2022-05-20 19:12:16,215] {dagbag.py:507} INFO - Filling up the DagBag from /opt/airflow/dags/ETL_Raizen.py
[2022-05-20 19:12:16,542] {logging_mixin.py:115} INFO - [2022-05-20 19:12:16,541] {dagbag.py:320} ERROR - Failed to import: /opt/airflow/dags/ETL_Raizen.py
Traceback (most recent call last):
  File "/home/airflow/.local/lib/python3.7/site-packages/airflow/models/dagbag.py", line 317, in parse
    loader.exec_module(new_module)
  File "<frozen importlib._bootstrap_external>", line 728, in exec_module
  File "<frozen importlib._bootstrap>", line 219, in _call_with_frames_removed
  File "/opt/airflow/dags/ETL_Raizen.py", line 107, in <module>
    with DAG('Teste_ETL_Raízen', start_date = datetime(2022,5,18),
NameError: name 'datetime' is not defined
[2022-05-20 19:12:16,542] {processor.py:653} WARNING - No viable dags retrieved from /opt/airflow/dags/ETL_Raizen.py
[2022-05-20 19:12:16,563] {processor.py:161} INFO - Processing /opt/airflow/dags/ETL_Raizen.py took 0.360 seconds
[2022-05-20 19:12:46,604] {processor.py:153} INFO - Started process (PID=1161) to work on /opt/airflow/dags/ETL_Raizen.py
[2022-05-20 19:12:46,611] {processor.py:641} INFO - Processing file /opt/airflow/dags/ETL_Raizen.py for tasks to queue
[2022-05-20 19:12:46,612] {logging_mixin.py:115} INFO - [2022-05-20 19:12:46,612] {dagbag.py:507} INFO - Filling up the DagBag from /opt/airflow/dags/ETL_Raizen.py
[2022-05-20 19:12:46,973] {logging_mixin.py:115} INFO - [2022-05-20 19:12:46,973] {dagbag.py:320} ERROR - Failed to import: /opt/airflow/dags/ETL_Raizen.py
Traceback (most recent call last):
  File "/home/airflow/.local/lib/python3.7/site-packages/airflow/models/dagbag.py", line 317, in parse
    loader.exec_module(new_module)
  File "<frozen importlib._bootstrap_external>", line 728, in exec_module
  File "<frozen importlib._bootstrap>", line 219, in _call_with_frames_removed
  File "/opt/airflow/dags/ETL_Raizen.py", line 107, in <module>
    with DAG('Teste_ETL_Raízen', start_date = datetime(2022,5,18),
NameError: name 'datetime' is not defined
[2022-05-20 19:12:46,973] {processor.py:653} WARNING - No viable dags retrieved from /opt/airflow/dags/ETL_Raizen.py
[2022-05-20 19:12:46,987] {processor.py:161} INFO - Processing /opt/airflow/dags/ETL_Raizen.py took 0.385 seconds
[2022-05-20 19:13:17,785] {processor.py:153} INFO - Started process (PID=1227) to work on /opt/airflow/dags/ETL_Raizen.py
[2022-05-20 19:13:17,793] {processor.py:641} INFO - Processing file /opt/airflow/dags/ETL_Raizen.py for tasks to queue
[2022-05-20 19:13:17,794] {logging_mixin.py:115} INFO - [2022-05-20 19:13:17,794] {dagbag.py:507} INFO - Filling up the DagBag from /opt/airflow/dags/ETL_Raizen.py
[2022-05-20 19:13:18,132] {logging_mixin.py:115} INFO - [2022-05-20 19:13:18,131] {dagbag.py:320} ERROR - Failed to import: /opt/airflow/dags/ETL_Raizen.py
Traceback (most recent call last):
  File "/home/airflow/.local/lib/python3.7/site-packages/airflow/models/dagbag.py", line 317, in parse
    loader.exec_module(new_module)
  File "<frozen importlib._bootstrap_external>", line 728, in exec_module
  File "<frozen importlib._bootstrap>", line 219, in _call_with_frames_removed
  File "/opt/airflow/dags/ETL_Raizen.py", line 107, in <module>
    with DAG('Teste_ETL_Raízen', start_date = datetime(2022,5,18),
NameError: name 'datetime' is not defined
[2022-05-20 19:13:18,132] {processor.py:653} WARNING - No viable dags retrieved from /opt/airflow/dags/ETL_Raizen.py
[2022-05-20 19:13:18,154] {processor.py:161} INFO - Processing /opt/airflow/dags/ETL_Raizen.py took 0.377 seconds
[2022-05-20 19:13:48,861] {processor.py:153} INFO - Started process (PID=1292) to work on /opt/airflow/dags/ETL_Raizen.py
[2022-05-20 19:13:48,870] {processor.py:641} INFO - Processing file /opt/airflow/dags/ETL_Raizen.py for tasks to queue
[2022-05-20 19:13:48,871] {logging_mixin.py:115} INFO - [2022-05-20 19:13:48,871] {dagbag.py:507} INFO - Filling up the DagBag from /opt/airflow/dags/ETL_Raizen.py
[2022-05-20 19:13:49,229] {logging_mixin.py:115} INFO - [2022-05-20 19:13:49,229] {dagbag.py:320} ERROR - Failed to import: /opt/airflow/dags/ETL_Raizen.py
Traceback (most recent call last):
  File "/home/airflow/.local/lib/python3.7/site-packages/airflow/models/dagbag.py", line 317, in parse
    loader.exec_module(new_module)
  File "<frozen importlib._bootstrap_external>", line 728, in exec_module
  File "<frozen importlib._bootstrap>", line 219, in _call_with_frames_removed
  File "/opt/airflow/dags/ETL_Raizen.py", line 107, in <module>
    with DAG('Teste_ETL_Raízen', start_date = datetime(2022,5,18),
NameError: name 'datetime' is not defined
[2022-05-20 19:13:49,230] {processor.py:653} WARNING - No viable dags retrieved from /opt/airflow/dags/ETL_Raizen.py
[2022-05-20 19:13:49,243] {processor.py:161} INFO - Processing /opt/airflow/dags/ETL_Raizen.py took 0.385 seconds
[2022-05-20 19:14:20,187] {processor.py:153} INFO - Started process (PID=1357) to work on /opt/airflow/dags/ETL_Raizen.py
[2022-05-20 19:14:20,188] {processor.py:641} INFO - Processing file /opt/airflow/dags/ETL_Raizen.py for tasks to queue
[2022-05-20 19:14:20,188] {logging_mixin.py:115} INFO - [2022-05-20 19:14:20,188] {dagbag.py:507} INFO - Filling up the DagBag from /opt/airflow/dags/ETL_Raizen.py
[2022-05-20 19:14:20,568] {logging_mixin.py:115} INFO - [2022-05-20 19:14:20,568] {dagbag.py:320} ERROR - Failed to import: /opt/airflow/dags/ETL_Raizen.py
Traceback (most recent call last):
  File "/home/airflow/.local/lib/python3.7/site-packages/airflow/models/dagbag.py", line 317, in parse
    loader.exec_module(new_module)
  File "<frozen importlib._bootstrap_external>", line 728, in exec_module
  File "<frozen importlib._bootstrap>", line 219, in _call_with_frames_removed
  File "/opt/airflow/dags/ETL_Raizen.py", line 107, in <module>
    with DAG('Teste_ETL_Raízen', start_date = datetime(2022,5,18),
NameError: name 'datetime' is not defined
[2022-05-20 19:14:20,569] {processor.py:653} WARNING - No viable dags retrieved from /opt/airflow/dags/ETL_Raizen.py
[2022-05-20 19:14:20,583] {processor.py:161} INFO - Processing /opt/airflow/dags/ETL_Raizen.py took 0.397 seconds
[2022-05-20 19:14:51,390] {processor.py:153} INFO - Started process (PID=1413) to work on /opt/airflow/dags/ETL_Raizen.py
[2022-05-20 19:14:51,398] {processor.py:641} INFO - Processing file /opt/airflow/dags/ETL_Raizen.py for tasks to queue
[2022-05-20 19:14:51,399] {logging_mixin.py:115} INFO - [2022-05-20 19:14:51,399] {dagbag.py:507} INFO - Filling up the DagBag from /opt/airflow/dags/ETL_Raizen.py
[2022-05-20 19:14:51,745] {logging_mixin.py:115} INFO - [2022-05-20 19:14:51,744] {dagbag.py:320} ERROR - Failed to import: /opt/airflow/dags/ETL_Raizen.py
Traceback (most recent call last):
  File "/home/airflow/.local/lib/python3.7/site-packages/airflow/models/dagbag.py", line 317, in parse
    loader.exec_module(new_module)
  File "<frozen importlib._bootstrap_external>", line 728, in exec_module
  File "<frozen importlib._bootstrap>", line 219, in _call_with_frames_removed
  File "/opt/airflow/dags/ETL_Raizen.py", line 107, in <module>
    with DAG('Teste_ETL_Raízen', start_date = datetime(2022,5,18),
NameError: name 'datetime' is not defined
[2022-05-20 19:14:51,745] {processor.py:653} WARNING - No viable dags retrieved from /opt/airflow/dags/ETL_Raizen.py
[2022-05-20 19:14:51,766] {processor.py:161} INFO - Processing /opt/airflow/dags/ETL_Raizen.py took 0.379 seconds
[2022-05-20 19:15:22,389] {processor.py:153} INFO - Started process (PID=1477) to work on /opt/airflow/dags/ETL_Raizen.py
[2022-05-20 19:15:22,397] {processor.py:641} INFO - Processing file /opt/airflow/dags/ETL_Raizen.py for tasks to queue
[2022-05-20 19:15:22,397] {logging_mixin.py:115} INFO - [2022-05-20 19:15:22,397] {dagbag.py:507} INFO - Filling up the DagBag from /opt/airflow/dags/ETL_Raizen.py
[2022-05-20 19:15:22,732] {logging_mixin.py:115} INFO - [2022-05-20 19:15:22,731] {dagbag.py:320} ERROR - Failed to import: /opt/airflow/dags/ETL_Raizen.py
Traceback (most recent call last):
  File "/home/airflow/.local/lib/python3.7/site-packages/airflow/models/dagbag.py", line 317, in parse
    loader.exec_module(new_module)
  File "<frozen importlib._bootstrap_external>", line 728, in exec_module
  File "<frozen importlib._bootstrap>", line 219, in _call_with_frames_removed
  File "/opt/airflow/dags/ETL_Raizen.py", line 107, in <module>
    with DAG('Teste_ETL_Raízen', start_date = datetime(2022,5,18),
NameError: name 'datetime' is not defined
[2022-05-20 19:15:22,732] {processor.py:653} WARNING - No viable dags retrieved from /opt/airflow/dags/ETL_Raizen.py
[2022-05-20 19:15:22,751] {processor.py:161} INFO - Processing /opt/airflow/dags/ETL_Raizen.py took 0.364 seconds
[2022-05-20 19:15:53,210] {processor.py:153} INFO - Started process (PID=1541) to work on /opt/airflow/dags/ETL_Raizen.py
[2022-05-20 19:15:53,219] {processor.py:641} INFO - Processing file /opt/airflow/dags/ETL_Raizen.py for tasks to queue
[2022-05-20 19:15:53,220] {logging_mixin.py:115} INFO - [2022-05-20 19:15:53,219] {dagbag.py:507} INFO - Filling up the DagBag from /opt/airflow/dags/ETL_Raizen.py
[2022-05-20 19:15:53,594] {logging_mixin.py:115} INFO - [2022-05-20 19:15:53,593] {dagbag.py:320} ERROR - Failed to import: /opt/airflow/dags/ETL_Raizen.py
Traceback (most recent call last):
  File "/home/airflow/.local/lib/python3.7/site-packages/airflow/models/dagbag.py", line 317, in parse
    loader.exec_module(new_module)
  File "<frozen importlib._bootstrap_external>", line 728, in exec_module
  File "<frozen importlib._bootstrap>", line 219, in _call_with_frames_removed
  File "/opt/airflow/dags/ETL_Raizen.py", line 107, in <module>
    with DAG('Teste_ETL_Raízen', start_date = datetime(2022,5,18),
NameError: name 'datetime' is not defined
[2022-05-20 19:15:53,594] {processor.py:653} WARNING - No viable dags retrieved from /opt/airflow/dags/ETL_Raizen.py
[2022-05-20 19:15:53,611] {processor.py:161} INFO - Processing /opt/airflow/dags/ETL_Raizen.py took 0.404 seconds
[2022-05-20 19:16:24,379] {processor.py:153} INFO - Started process (PID=1605) to work on /opt/airflow/dags/ETL_Raizen.py
[2022-05-20 19:16:24,379] {processor.py:641} INFO - Processing file /opt/airflow/dags/ETL_Raizen.py for tasks to queue
[2022-05-20 19:16:24,380] {logging_mixin.py:115} INFO - [2022-05-20 19:16:24,380] {dagbag.py:507} INFO - Filling up the DagBag from /opt/airflow/dags/ETL_Raizen.py
[2022-05-20 19:16:24,793] {logging_mixin.py:115} INFO - [2022-05-20 19:16:24,792] {dagbag.py:320} ERROR - Failed to import: /opt/airflow/dags/ETL_Raizen.py
Traceback (most recent call last):
  File "/home/airflow/.local/lib/python3.7/site-packages/airflow/models/dagbag.py", line 317, in parse
    loader.exec_module(new_module)
  File "<frozen importlib._bootstrap_external>", line 728, in exec_module
  File "<frozen importlib._bootstrap>", line 219, in _call_with_frames_removed
  File "/opt/airflow/dags/ETL_Raizen.py", line 107, in <module>
    with DAG('Teste_ETL_Raízen', start_date = datetime(2022,5,18),
NameError: name 'datetime' is not defined
[2022-05-20 19:16:24,793] {processor.py:653} WARNING - No viable dags retrieved from /opt/airflow/dags/ETL_Raizen.py
[2022-05-20 19:16:24,809] {processor.py:161} INFO - Processing /opt/airflow/dags/ETL_Raizen.py took 0.432 seconds
[2022-05-20 19:16:54,928] {processor.py:153} INFO - Started process (PID=1663) to work on /opt/airflow/dags/ETL_Raizen.py
[2022-05-20 19:16:54,929] {processor.py:641} INFO - Processing file /opt/airflow/dags/ETL_Raizen.py for tasks to queue
[2022-05-20 19:16:54,929] {logging_mixin.py:115} INFO - [2022-05-20 19:16:54,929] {dagbag.py:507} INFO - Filling up the DagBag from /opt/airflow/dags/ETL_Raizen.py
[2022-05-20 19:16:55,269] {logging_mixin.py:115} INFO - [2022-05-20 19:16:55,268] {dagbag.py:320} ERROR - Failed to import: /opt/airflow/dags/ETL_Raizen.py
Traceback (most recent call last):
  File "/home/airflow/.local/lib/python3.7/site-packages/airflow/models/dagbag.py", line 317, in parse
    loader.exec_module(new_module)
  File "<frozen importlib._bootstrap_external>", line 728, in exec_module
  File "<frozen importlib._bootstrap>", line 219, in _call_with_frames_removed
  File "/opt/airflow/dags/ETL_Raizen.py", line 107, in <module>
    with DAG('Teste_ETL_Raízen', start_date = datetime(2022,5,18),
NameError: name 'datetime' is not defined
[2022-05-20 19:16:55,269] {processor.py:653} WARNING - No viable dags retrieved from /opt/airflow/dags/ETL_Raizen.py
[2022-05-20 19:16:55,282] {processor.py:161} INFO - Processing /opt/airflow/dags/ETL_Raizen.py took 0.356 seconds
[2022-05-20 19:17:25,379] {processor.py:153} INFO - Started process (PID=1729) to work on /opt/airflow/dags/ETL_Raizen.py
[2022-05-20 19:17:25,387] {processor.py:641} INFO - Processing file /opt/airflow/dags/ETL_Raizen.py for tasks to queue
[2022-05-20 19:17:25,387] {logging_mixin.py:115} INFO - [2022-05-20 19:17:25,387] {dagbag.py:507} INFO - Filling up the DagBag from /opt/airflow/dags/ETL_Raizen.py
[2022-05-20 19:17:25,714] {logging_mixin.py:115} INFO - [2022-05-20 19:17:25,714] {dagbag.py:320} ERROR - Failed to import: /opt/airflow/dags/ETL_Raizen.py
Traceback (most recent call last):
  File "/home/airflow/.local/lib/python3.7/site-packages/airflow/models/dagbag.py", line 317, in parse
    loader.exec_module(new_module)
  File "<frozen importlib._bootstrap_external>", line 728, in exec_module
  File "<frozen importlib._bootstrap>", line 219, in _call_with_frames_removed
  File "/opt/airflow/dags/ETL_Raizen.py", line 107, in <module>
    with DAG('Teste_ETL_Raízen', start_date = datetime(2022,5,18),
NameError: name 'datetime' is not defined
[2022-05-20 19:17:25,714] {processor.py:653} WARNING - No viable dags retrieved from /opt/airflow/dags/ETL_Raizen.py
[2022-05-20 19:17:25,735] {processor.py:161} INFO - Processing /opt/airflow/dags/ETL_Raizen.py took 0.359 seconds
[2022-05-20 19:17:56,542] {processor.py:153} INFO - Started process (PID=1794) to work on /opt/airflow/dags/ETL_Raizen.py
[2022-05-20 19:17:56,543] {processor.py:641} INFO - Processing file /opt/airflow/dags/ETL_Raizen.py for tasks to queue
[2022-05-20 19:17:56,543] {logging_mixin.py:115} INFO - [2022-05-20 19:17:56,543] {dagbag.py:507} INFO - Filling up the DagBag from /opt/airflow/dags/ETL_Raizen.py
[2022-05-20 19:17:56,876] {logging_mixin.py:115} INFO - [2022-05-20 19:17:56,875] {dagbag.py:320} ERROR - Failed to import: /opt/airflow/dags/ETL_Raizen.py
Traceback (most recent call last):
  File "/home/airflow/.local/lib/python3.7/site-packages/airflow/models/dagbag.py", line 317, in parse
    loader.exec_module(new_module)
  File "<frozen importlib._bootstrap_external>", line 728, in exec_module
  File "<frozen importlib._bootstrap>", line 219, in _call_with_frames_removed
  File "/opt/airflow/dags/ETL_Raizen.py", line 107, in <module>
    with DAG('Teste_ETL_Raízen', start_date = datetime(2022,5,18),
NameError: name 'datetime' is not defined
[2022-05-20 19:17:56,876] {processor.py:653} WARNING - No viable dags retrieved from /opt/airflow/dags/ETL_Raizen.py
[2022-05-20 19:17:56,891] {processor.py:161} INFO - Processing /opt/airflow/dags/ETL_Raizen.py took 0.350 seconds
[2022-05-20 19:18:27,451] {processor.py:153} INFO - Started process (PID=1850) to work on /opt/airflow/dags/ETL_Raizen.py
[2022-05-20 19:18:27,452] {processor.py:641} INFO - Processing file /opt/airflow/dags/ETL_Raizen.py for tasks to queue
[2022-05-20 19:18:27,453] {logging_mixin.py:115} INFO - [2022-05-20 19:18:27,453] {dagbag.py:507} INFO - Filling up the DagBag from /opt/airflow/dags/ETL_Raizen.py
[2022-05-20 19:18:27,836] {logging_mixin.py:115} INFO - [2022-05-20 19:18:27,835] {dagbag.py:320} ERROR - Failed to import: /opt/airflow/dags/ETL_Raizen.py
Traceback (most recent call last):
  File "/home/airflow/.local/lib/python3.7/site-packages/airflow/models/dagbag.py", line 317, in parse
    loader.exec_module(new_module)
  File "<frozen importlib._bootstrap_external>", line 728, in exec_module
  File "<frozen importlib._bootstrap>", line 219, in _call_with_frames_removed
  File "/opt/airflow/dags/ETL_Raizen.py", line 107, in <module>
    with DAG('Teste_ETL_Raízen', start_date = datetime(2022,5,18),
NameError: name 'datetime' is not defined
[2022-05-20 19:18:27,836] {processor.py:653} WARNING - No viable dags retrieved from /opt/airflow/dags/ETL_Raizen.py
[2022-05-20 19:18:27,849] {processor.py:161} INFO - Processing /opt/airflow/dags/ETL_Raizen.py took 0.407 seconds
[2022-05-20 19:18:58,270] {processor.py:153} INFO - Started process (PID=1914) to work on /opt/airflow/dags/ETL_Raizen.py
[2022-05-20 19:18:58,270] {processor.py:641} INFO - Processing file /opt/airflow/dags/ETL_Raizen.py for tasks to queue
[2022-05-20 19:18:58,270] {logging_mixin.py:115} INFO - [2022-05-20 19:18:58,270] {dagbag.py:507} INFO - Filling up the DagBag from /opt/airflow/dags/ETL_Raizen.py
[2022-05-20 19:18:58,747] {logging_mixin.py:115} INFO - [2022-05-20 19:18:58,747] {dagbag.py:320} ERROR - Failed to import: /opt/airflow/dags/ETL_Raizen.py
Traceback (most recent call last):
  File "/home/airflow/.local/lib/python3.7/site-packages/airflow/models/dagbag.py", line 317, in parse
    loader.exec_module(new_module)
  File "<frozen importlib._bootstrap_external>", line 728, in exec_module
  File "<frozen importlib._bootstrap>", line 219, in _call_with_frames_removed
  File "/opt/airflow/dags/ETL_Raizen.py", line 107, in <module>
    with DAG('Teste_ETL_Raízen', start_date = datetime(2022,5,18),
NameError: name 'datetime' is not defined
[2022-05-20 19:18:58,748] {processor.py:653} WARNING - No viable dags retrieved from /opt/airflow/dags/ETL_Raizen.py
[2022-05-20 19:18:58,767] {processor.py:161} INFO - Processing /opt/airflow/dags/ETL_Raizen.py took 0.499 seconds
[2022-05-20 19:19:29,291] {processor.py:153} INFO - Started process (PID=1979) to work on /opt/airflow/dags/ETL_Raizen.py
[2022-05-20 19:19:29,291] {processor.py:641} INFO - Processing file /opt/airflow/dags/ETL_Raizen.py for tasks to queue
[2022-05-20 19:19:29,292] {logging_mixin.py:115} INFO - [2022-05-20 19:19:29,292] {dagbag.py:507} INFO - Filling up the DagBag from /opt/airflow/dags/ETL_Raizen.py
[2022-05-20 19:19:29,667] {logging_mixin.py:115} INFO - [2022-05-20 19:19:29,666] {dagbag.py:320} ERROR - Failed to import: /opt/airflow/dags/ETL_Raizen.py
Traceback (most recent call last):
  File "/home/airflow/.local/lib/python3.7/site-packages/airflow/models/dagbag.py", line 317, in parse
    loader.exec_module(new_module)
  File "<frozen importlib._bootstrap_external>", line 728, in exec_module
  File "<frozen importlib._bootstrap>", line 219, in _call_with_frames_removed
  File "/opt/airflow/dags/ETL_Raizen.py", line 107, in <module>
    with DAG('Teste_ETL_Raízen', start_date = datetime(2022,5,18),
NameError: name 'datetime' is not defined
[2022-05-20 19:19:29,667] {processor.py:653} WARNING - No viable dags retrieved from /opt/airflow/dags/ETL_Raizen.py
[2022-05-20 19:19:29,681] {processor.py:161} INFO - Processing /opt/airflow/dags/ETL_Raizen.py took 0.392 seconds
[2022-05-20 19:20:00,538] {processor.py:153} INFO - Started process (PID=2035) to work on /opt/airflow/dags/ETL_Raizen.py
[2022-05-20 19:20:00,546] {processor.py:641} INFO - Processing file /opt/airflow/dags/ETL_Raizen.py for tasks to queue
[2022-05-20 19:20:00,547] {logging_mixin.py:115} INFO - [2022-05-20 19:20:00,547] {dagbag.py:507} INFO - Filling up the DagBag from /opt/airflow/dags/ETL_Raizen.py
[2022-05-20 19:20:00,890] {logging_mixin.py:115} INFO - [2022-05-20 19:20:00,890] {dagbag.py:320} ERROR - Failed to import: /opt/airflow/dags/ETL_Raizen.py
Traceback (most recent call last):
  File "/home/airflow/.local/lib/python3.7/site-packages/airflow/models/dagbag.py", line 317, in parse
    loader.exec_module(new_module)
  File "<frozen importlib._bootstrap_external>", line 728, in exec_module
  File "<frozen importlib._bootstrap>", line 219, in _call_with_frames_removed
  File "/opt/airflow/dags/ETL_Raizen.py", line 107, in <module>
    with DAG('Teste_ETL_Raízen', start_date = datetime(2022,5,18),
NameError: name 'datetime' is not defined
[2022-05-20 19:20:00,890] {processor.py:653} WARNING - No viable dags retrieved from /opt/airflow/dags/ETL_Raizen.py
[2022-05-20 19:20:00,907] {processor.py:161} INFO - Processing /opt/airflow/dags/ETL_Raizen.py took 0.373 seconds
[2022-05-20 19:20:31,703] {processor.py:153} INFO - Started process (PID=2100) to work on /opt/airflow/dags/ETL_Raizen.py
[2022-05-20 19:20:31,711] {processor.py:641} INFO - Processing file /opt/airflow/dags/ETL_Raizen.py for tasks to queue
[2022-05-20 19:20:31,711] {logging_mixin.py:115} INFO - [2022-05-20 19:20:31,711] {dagbag.py:507} INFO - Filling up the DagBag from /opt/airflow/dags/ETL_Raizen.py
[2022-05-20 19:20:32,033] {logging_mixin.py:115} INFO - [2022-05-20 19:20:32,033] {dagbag.py:320} ERROR - Failed to import: /opt/airflow/dags/ETL_Raizen.py
Traceback (most recent call last):
  File "/home/airflow/.local/lib/python3.7/site-packages/airflow/models/dagbag.py", line 317, in parse
    loader.exec_module(new_module)
  File "<frozen importlib._bootstrap_external>", line 728, in exec_module
  File "<frozen importlib._bootstrap>", line 219, in _call_with_frames_removed
  File "/opt/airflow/dags/ETL_Raizen.py", line 107, in <module>
    with DAG('Teste_ETL_Raízen', start_date = datetime(2022,5,18),
NameError: name 'datetime' is not defined
[2022-05-20 19:20:32,034] {processor.py:653} WARNING - No viable dags retrieved from /opt/airflow/dags/ETL_Raizen.py
[2022-05-20 19:20:32,048] {processor.py:161} INFO - Processing /opt/airflow/dags/ETL_Raizen.py took 0.347 seconds
[2022-05-20 19:21:02,491] {processor.py:153} INFO - Started process (PID=2164) to work on /opt/airflow/dags/ETL_Raizen.py
[2022-05-20 19:21:02,491] {processor.py:641} INFO - Processing file /opt/airflow/dags/ETL_Raizen.py for tasks to queue
[2022-05-20 19:21:02,492] {logging_mixin.py:115} INFO - [2022-05-20 19:21:02,492] {dagbag.py:507} INFO - Filling up the DagBag from /opt/airflow/dags/ETL_Raizen.py
[2022-05-20 19:21:02,824] {logging_mixin.py:115} INFO - [2022-05-20 19:21:02,823] {dagbag.py:320} ERROR - Failed to import: /opt/airflow/dags/ETL_Raizen.py
Traceback (most recent call last):
  File "/home/airflow/.local/lib/python3.7/site-packages/airflow/models/dagbag.py", line 317, in parse
    loader.exec_module(new_module)
  File "<frozen importlib._bootstrap_external>", line 728, in exec_module
  File "<frozen importlib._bootstrap>", line 219, in _call_with_frames_removed
  File "/opt/airflow/dags/ETL_Raizen.py", line 107, in <module>
    with DAG('Teste_ETL_Raízen', start_date = datetime(2022,5,18),
NameError: name 'datetime' is not defined
[2022-05-20 19:21:02,824] {processor.py:653} WARNING - No viable dags retrieved from /opt/airflow/dags/ETL_Raizen.py
[2022-05-20 19:21:02,837] {processor.py:161} INFO - Processing /opt/airflow/dags/ETL_Raizen.py took 0.348 seconds
[2022-05-20 19:21:33,589] {processor.py:153} INFO - Started process (PID=2229) to work on /opt/airflow/dags/ETL_Raizen.py
[2022-05-20 19:21:33,597] {processor.py:641} INFO - Processing file /opt/airflow/dags/ETL_Raizen.py for tasks to queue
[2022-05-20 19:21:33,597] {logging_mixin.py:115} INFO - [2022-05-20 19:21:33,597] {dagbag.py:507} INFO - Filling up the DagBag from /opt/airflow/dags/ETL_Raizen.py
[2022-05-20 19:21:33,918] {logging_mixin.py:115} INFO - [2022-05-20 19:21:33,918] {dagbag.py:320} ERROR - Failed to import: /opt/airflow/dags/ETL_Raizen.py
Traceback (most recent call last):
  File "/home/airflow/.local/lib/python3.7/site-packages/airflow/models/dagbag.py", line 317, in parse
    loader.exec_module(new_module)
  File "<frozen importlib._bootstrap_external>", line 728, in exec_module
  File "<frozen importlib._bootstrap>", line 219, in _call_with_frames_removed
  File "/opt/airflow/dags/ETL_Raizen.py", line 107, in <module>
    with DAG('Teste_ETL_Raízen', start_date = datetime(2022,5,18),
NameError: name 'datetime' is not defined
[2022-05-20 19:21:33,919] {processor.py:653} WARNING - No viable dags retrieved from /opt/airflow/dags/ETL_Raizen.py
[2022-05-20 19:21:33,939] {processor.py:161} INFO - Processing /opt/airflow/dags/ETL_Raizen.py took 0.352 seconds
[2022-05-20 19:22:04,008] {processor.py:153} INFO - Started process (PID=2285) to work on /opt/airflow/dags/ETL_Raizen.py
[2022-05-20 19:22:04,008] {processor.py:641} INFO - Processing file /opt/airflow/dags/ETL_Raizen.py for tasks to queue
[2022-05-20 19:22:04,009] {logging_mixin.py:115} INFO - [2022-05-20 19:22:04,009] {dagbag.py:507} INFO - Filling up the DagBag from /opt/airflow/dags/ETL_Raizen.py
[2022-05-20 19:22:04,337] {logging_mixin.py:115} INFO - [2022-05-20 19:22:04,336] {dagbag.py:320} ERROR - Failed to import: /opt/airflow/dags/ETL_Raizen.py
Traceback (most recent call last):
  File "/home/airflow/.local/lib/python3.7/site-packages/airflow/models/dagbag.py", line 317, in parse
    loader.exec_module(new_module)
  File "<frozen importlib._bootstrap_external>", line 728, in exec_module
  File "<frozen importlib._bootstrap>", line 219, in _call_with_frames_removed
  File "/opt/airflow/dags/ETL_Raizen.py", line 107, in <module>
    with DAG('Teste_ETL_Raízen', start_date = datetime(2022,5,18),
NameError: name 'datetime' is not defined
[2022-05-20 19:22:04,337] {processor.py:653} WARNING - No viable dags retrieved from /opt/airflow/dags/ETL_Raizen.py
[2022-05-20 19:22:04,351] {processor.py:161} INFO - Processing /opt/airflow/dags/ETL_Raizen.py took 0.345 seconds
[2022-05-20 19:22:35,262] {processor.py:153} INFO - Started process (PID=2349) to work on /opt/airflow/dags/ETL_Raizen.py
[2022-05-20 19:22:35,271] {processor.py:641} INFO - Processing file /opt/airflow/dags/ETL_Raizen.py for tasks to queue
[2022-05-20 19:22:35,272] {logging_mixin.py:115} INFO - [2022-05-20 19:22:35,272] {dagbag.py:507} INFO - Filling up the DagBag from /opt/airflow/dags/ETL_Raizen.py
[2022-05-20 19:22:35,617] {logging_mixin.py:115} INFO - [2022-05-20 19:22:35,616] {dagbag.py:320} ERROR - Failed to import: /opt/airflow/dags/ETL_Raizen.py
Traceback (most recent call last):
  File "/home/airflow/.local/lib/python3.7/site-packages/airflow/models/dagbag.py", line 317, in parse
    loader.exec_module(new_module)
  File "<frozen importlib._bootstrap_external>", line 728, in exec_module
  File "<frozen importlib._bootstrap>", line 219, in _call_with_frames_removed
  File "/opt/airflow/dags/ETL_Raizen.py", line 107, in <module>
    with DAG('Teste_ETL_Raízen', start_date = datetime(2022,5,18),
NameError: name 'datetime' is not defined
[2022-05-20 19:22:35,617] {processor.py:653} WARNING - No viable dags retrieved from /opt/airflow/dags/ETL_Raizen.py
[2022-05-20 19:22:35,630] {processor.py:161} INFO - Processing /opt/airflow/dags/ETL_Raizen.py took 0.370 seconds
[2022-05-20 19:23:05,679] {processor.py:153} INFO - Started process (PID=2414) to work on /opt/airflow/dags/ETL_Raizen.py
[2022-05-20 19:23:05,680] {processor.py:641} INFO - Processing file /opt/airflow/dags/ETL_Raizen.py for tasks to queue
[2022-05-20 19:23:05,680] {logging_mixin.py:115} INFO - [2022-05-20 19:23:05,680] {dagbag.py:507} INFO - Filling up the DagBag from /opt/airflow/dags/ETL_Raizen.py
[2022-05-20 19:23:06,048] {logging_mixin.py:115} INFO - [2022-05-20 19:23:06,047] {dagbag.py:320} ERROR - Failed to import: /opt/airflow/dags/ETL_Raizen.py
Traceback (most recent call last):
  File "/home/airflow/.local/lib/python3.7/site-packages/airflow/models/dagbag.py", line 317, in parse
    loader.exec_module(new_module)
  File "<frozen importlib._bootstrap_external>", line 728, in exec_module
  File "<frozen importlib._bootstrap>", line 219, in _call_with_frames_removed
  File "/opt/airflow/dags/ETL_Raizen.py", line 107, in <module>
    with DAG('Teste_ETL_Raízen', start_date = datetime(2022,5,18),
NameError: name 'datetime' is not defined
[2022-05-20 19:23:06,048] {processor.py:653} WARNING - No viable dags retrieved from /opt/airflow/dags/ETL_Raizen.py
[2022-05-20 19:23:06,064] {processor.py:161} INFO - Processing /opt/airflow/dags/ETL_Raizen.py took 0.386 seconds
[2022-05-20 19:23:36,101] {processor.py:153} INFO - Started process (PID=2470) to work on /opt/airflow/dags/ETL_Raizen.py
[2022-05-20 19:23:36,102] {processor.py:641} INFO - Processing file /opt/airflow/dags/ETL_Raizen.py for tasks to queue
[2022-05-20 19:23:36,103] {logging_mixin.py:115} INFO - [2022-05-20 19:23:36,102] {dagbag.py:507} INFO - Filling up the DagBag from /opt/airflow/dags/ETL_Raizen.py
[2022-05-20 19:23:36,465] {logging_mixin.py:115} INFO - [2022-05-20 19:23:36,464] {dagbag.py:320} ERROR - Failed to import: /opt/airflow/dags/ETL_Raizen.py
Traceback (most recent call last):
  File "/home/airflow/.local/lib/python3.7/site-packages/airflow/models/dagbag.py", line 317, in parse
    loader.exec_module(new_module)
  File "<frozen importlib._bootstrap_external>", line 728, in exec_module
  File "<frozen importlib._bootstrap>", line 219, in _call_with_frames_removed
  File "/opt/airflow/dags/ETL_Raizen.py", line 107, in <module>
    with DAG('Teste_ETL_Raízen', start_date = datetime(2022,5,18),
NameError: name 'datetime' is not defined
[2022-05-20 19:23:36,465] {processor.py:653} WARNING - No viable dags retrieved from /opt/airflow/dags/ETL_Raizen.py
[2022-05-20 19:23:36,482] {processor.py:161} INFO - Processing /opt/airflow/dags/ETL_Raizen.py took 0.383 seconds
[2022-05-20 19:24:06,516] {processor.py:153} INFO - Started process (PID=2536) to work on /opt/airflow/dags/ETL_Raizen.py
[2022-05-20 19:24:06,519] {processor.py:641} INFO - Processing file /opt/airflow/dags/ETL_Raizen.py for tasks to queue
[2022-05-20 19:24:06,519] {logging_mixin.py:115} INFO - [2022-05-20 19:24:06,519] {dagbag.py:507} INFO - Filling up the DagBag from /opt/airflow/dags/ETL_Raizen.py
[2022-05-20 19:24:06,832] {logging_mixin.py:115} INFO - [2022-05-20 19:24:06,831] {dagbag.py:320} ERROR - Failed to import: /opt/airflow/dags/ETL_Raizen.py
Traceback (most recent call last):
  File "/home/airflow/.local/lib/python3.7/site-packages/airflow/models/dagbag.py", line 317, in parse
    loader.exec_module(new_module)
  File "<frozen importlib._bootstrap_external>", line 728, in exec_module
  File "<frozen importlib._bootstrap>", line 219, in _call_with_frames_removed
  File "/opt/airflow/dags/ETL_Raizen.py", line 107, in <module>
    with DAG('Teste_ETL_Raízen', start_date = datetime(2022,5,18),
NameError: name 'datetime' is not defined
[2022-05-20 19:24:06,832] {processor.py:653} WARNING - No viable dags retrieved from /opt/airflow/dags/ETL_Raizen.py
[2022-05-20 19:24:06,852] {processor.py:161} INFO - Processing /opt/airflow/dags/ETL_Raizen.py took 0.339 seconds
[2022-05-20 19:24:36,882] {processor.py:153} INFO - Started process (PID=2599) to work on /opt/airflow/dags/ETL_Raizen.py
[2022-05-20 19:24:36,882] {processor.py:641} INFO - Processing file /opt/airflow/dags/ETL_Raizen.py for tasks to queue
[2022-05-20 19:24:36,883] {logging_mixin.py:115} INFO - [2022-05-20 19:24:36,882] {dagbag.py:507} INFO - Filling up the DagBag from /opt/airflow/dags/ETL_Raizen.py
[2022-05-20 19:24:37,214] {logging_mixin.py:115} INFO - [2022-05-20 19:24:37,214] {dagbag.py:320} ERROR - Failed to import: /opt/airflow/dags/ETL_Raizen.py
Traceback (most recent call last):
  File "/home/airflow/.local/lib/python3.7/site-packages/airflow/models/dagbag.py", line 317, in parse
    loader.exec_module(new_module)
  File "<frozen importlib._bootstrap_external>", line 728, in exec_module
  File "<frozen importlib._bootstrap>", line 219, in _call_with_frames_removed
  File "/opt/airflow/dags/ETL_Raizen.py", line 107, in <module>
    with DAG('Teste_ETL_Raízen', start_date = datetime(2022,5,18),
NameError: name 'datetime' is not defined
[2022-05-20 19:24:37,215] {processor.py:653} WARNING - No viable dags retrieved from /opt/airflow/dags/ETL_Raizen.py
[2022-05-20 19:24:37,227] {processor.py:161} INFO - Processing /opt/airflow/dags/ETL_Raizen.py took 0.347 seconds
[2022-05-20 19:25:07,588] {processor.py:153} INFO - Started process (PID=2655) to work on /opt/airflow/dags/ETL_Raizen.py
[2022-05-20 19:25:07,588] {processor.py:641} INFO - Processing file /opt/airflow/dags/ETL_Raizen.py for tasks to queue
[2022-05-20 19:25:07,588] {logging_mixin.py:115} INFO - [2022-05-20 19:25:07,588] {dagbag.py:507} INFO - Filling up the DagBag from /opt/airflow/dags/ETL_Raizen.py
[2022-05-20 19:25:07,933] {logging_mixin.py:115} INFO - [2022-05-20 19:25:07,933] {dagbag.py:320} ERROR - Failed to import: /opt/airflow/dags/ETL_Raizen.py
Traceback (most recent call last):
  File "/home/airflow/.local/lib/python3.7/site-packages/airflow/models/dagbag.py", line 317, in parse
    loader.exec_module(new_module)
  File "<frozen importlib._bootstrap_external>", line 728, in exec_module
  File "<frozen importlib._bootstrap>", line 219, in _call_with_frames_removed
  File "/opt/airflow/dags/ETL_Raizen.py", line 107, in <module>
    with DAG('Teste_ETL_Raízen', start_date = datetime(2022,5,18),
NameError: name 'datetime' is not defined
[2022-05-20 19:25:07,934] {processor.py:653} WARNING - No viable dags retrieved from /opt/airflow/dags/ETL_Raizen.py
[2022-05-20 19:25:07,949] {processor.py:161} INFO - Processing /opt/airflow/dags/ETL_Raizen.py took 0.364 seconds
[2022-05-20 19:25:37,987] {processor.py:153} INFO - Started process (PID=2720) to work on /opt/airflow/dags/ETL_Raizen.py
[2022-05-20 19:25:37,994] {processor.py:641} INFO - Processing file /opt/airflow/dags/ETL_Raizen.py for tasks to queue
[2022-05-20 19:25:37,995] {logging_mixin.py:115} INFO - [2022-05-20 19:25:37,995] {dagbag.py:507} INFO - Filling up the DagBag from /opt/airflow/dags/ETL_Raizen.py
[2022-05-20 19:25:38,327] {logging_mixin.py:115} INFO - [2022-05-20 19:25:38,326] {dagbag.py:320} ERROR - Failed to import: /opt/airflow/dags/ETL_Raizen.py
Traceback (most recent call last):
  File "/home/airflow/.local/lib/python3.7/site-packages/airflow/models/dagbag.py", line 317, in parse
    loader.exec_module(new_module)
  File "<frozen importlib._bootstrap_external>", line 728, in exec_module
  File "<frozen importlib._bootstrap>", line 219, in _call_with_frames_removed
  File "/opt/airflow/dags/ETL_Raizen.py", line 107, in <module>
    with DAG('Teste_ETL_Raízen', start_date = datetime(2022,5,18),
NameError: name 'datetime' is not defined
[2022-05-20 19:25:38,327] {processor.py:653} WARNING - No viable dags retrieved from /opt/airflow/dags/ETL_Raizen.py
[2022-05-20 19:25:38,340] {processor.py:161} INFO - Processing /opt/airflow/dags/ETL_Raizen.py took 0.356 seconds
[2022-05-20 19:26:08,925] {processor.py:153} INFO - Started process (PID=2785) to work on /opt/airflow/dags/ETL_Raizen.py
[2022-05-20 19:26:08,933] {processor.py:641} INFO - Processing file /opt/airflow/dags/ETL_Raizen.py for tasks to queue
[2022-05-20 19:26:08,935] {logging_mixin.py:115} INFO - [2022-05-20 19:26:08,935] {dagbag.py:507} INFO - Filling up the DagBag from /opt/airflow/dags/ETL_Raizen.py
[2022-05-20 19:26:09,277] {logging_mixin.py:115} INFO - [2022-05-20 19:26:09,276] {dagbag.py:320} ERROR - Failed to import: /opt/airflow/dags/ETL_Raizen.py
Traceback (most recent call last):
  File "/home/airflow/.local/lib/python3.7/site-packages/airflow/models/dagbag.py", line 317, in parse
    loader.exec_module(new_module)
  File "<frozen importlib._bootstrap_external>", line 728, in exec_module
  File "<frozen importlib._bootstrap>", line 219, in _call_with_frames_removed
  File "/opt/airflow/dags/ETL_Raizen.py", line 107, in <module>
    with DAG('Teste_ETL_Raízen', start_date = datetime(2022,5,18),
NameError: name 'datetime' is not defined
[2022-05-20 19:26:09,277] {processor.py:653} WARNING - No viable dags retrieved from /opt/airflow/dags/ETL_Raizen.py
[2022-05-20 19:26:09,297] {processor.py:161} INFO - Processing /opt/airflow/dags/ETL_Raizen.py took 0.374 seconds
[2022-05-20 19:26:39,987] {processor.py:153} INFO - Started process (PID=2851) to work on /opt/airflow/dags/ETL_Raizen.py
[2022-05-20 19:26:39,988] {processor.py:641} INFO - Processing file /opt/airflow/dags/ETL_Raizen.py for tasks to queue
[2022-05-20 19:26:39,988] {logging_mixin.py:115} INFO - [2022-05-20 19:26:39,988] {dagbag.py:507} INFO - Filling up the DagBag from /opt/airflow/dags/ETL_Raizen.py
[2022-05-20 19:26:40,338] {logging_mixin.py:115} INFO - [2022-05-20 19:26:40,337] {dagbag.py:320} ERROR - Failed to import: /opt/airflow/dags/ETL_Raizen.py
Traceback (most recent call last):
  File "/home/airflow/.local/lib/python3.7/site-packages/airflow/models/dagbag.py", line 317, in parse
    loader.exec_module(new_module)
  File "<frozen importlib._bootstrap_external>", line 728, in exec_module
  File "<frozen importlib._bootstrap>", line 219, in _call_with_frames_removed
  File "/opt/airflow/dags/ETL_Raizen.py", line 107, in <module>
    with DAG('Teste_ETL_Raízen', start_date = datetime(2022,5,18),
NameError: name 'datetime' is not defined
[2022-05-20 19:26:40,338] {processor.py:653} WARNING - No viable dags retrieved from /opt/airflow/dags/ETL_Raizen.py
[2022-05-20 19:26:40,351] {processor.py:161} INFO - Processing /opt/airflow/dags/ETL_Raizen.py took 0.367 seconds
[2022-05-20 19:27:11,012] {processor.py:153} INFO - Started process (PID=2907) to work on /opt/airflow/dags/ETL_Raizen.py
[2022-05-20 19:27:11,012] {processor.py:641} INFO - Processing file /opt/airflow/dags/ETL_Raizen.py for tasks to queue
[2022-05-20 19:27:11,012] {logging_mixin.py:115} INFO - [2022-05-20 19:27:11,012] {dagbag.py:507} INFO - Filling up the DagBag from /opt/airflow/dags/ETL_Raizen.py
[2022-05-20 19:27:11,337] {logging_mixin.py:115} INFO - [2022-05-20 19:27:11,337] {dagbag.py:320} ERROR - Failed to import: /opt/airflow/dags/ETL_Raizen.py
Traceback (most recent call last):
  File "/home/airflow/.local/lib/python3.7/site-packages/airflow/models/dagbag.py", line 317, in parse
    loader.exec_module(new_module)
  File "<frozen importlib._bootstrap_external>", line 728, in exec_module
  File "<frozen importlib._bootstrap>", line 219, in _call_with_frames_removed
  File "/opt/airflow/dags/ETL_Raizen.py", line 107, in <module>
    with DAG('Teste_ETL_Raízen', start_date = datetime(2022,5,18),
NameError: name 'datetime' is not defined
[2022-05-20 19:27:11,337] {processor.py:653} WARNING - No viable dags retrieved from /opt/airflow/dags/ETL_Raizen.py
[2022-05-20 19:27:11,351] {processor.py:161} INFO - Processing /opt/airflow/dags/ETL_Raizen.py took 0.341 seconds
[2022-05-20 19:27:42,139] {processor.py:153} INFO - Started process (PID=2972) to work on /opt/airflow/dags/ETL_Raizen.py
[2022-05-20 19:27:42,140] {processor.py:641} INFO - Processing file /opt/airflow/dags/ETL_Raizen.py for tasks to queue
[2022-05-20 19:27:42,140] {logging_mixin.py:115} INFO - [2022-05-20 19:27:42,140] {dagbag.py:507} INFO - Filling up the DagBag from /opt/airflow/dags/ETL_Raizen.py
[2022-05-20 19:27:42,449] {logging_mixin.py:115} INFO - [2022-05-20 19:27:42,449] {dagbag.py:320} ERROR - Failed to import: /opt/airflow/dags/ETL_Raizen.py
Traceback (most recent call last):
  File "/home/airflow/.local/lib/python3.7/site-packages/airflow/models/dagbag.py", line 317, in parse
    loader.exec_module(new_module)
  File "<frozen importlib._bootstrap_external>", line 728, in exec_module
  File "<frozen importlib._bootstrap>", line 219, in _call_with_frames_removed
  File "/opt/airflow/dags/ETL_Raizen.py", line 107, in <module>
    with DAG('Teste_ETL_Raízen', start_date = datetime(2022,5,18),
NameError: name 'datetime' is not defined
[2022-05-20 19:27:42,450] {processor.py:653} WARNING - No viable dags retrieved from /opt/airflow/dags/ETL_Raizen.py
[2022-05-20 19:27:42,470] {processor.py:161} INFO - Processing /opt/airflow/dags/ETL_Raizen.py took 0.333 seconds
[2022-05-20 19:28:13,474] {processor.py:153} INFO - Started process (PID=3037) to work on /opt/airflow/dags/ETL_Raizen.py
[2022-05-20 19:28:13,474] {processor.py:641} INFO - Processing file /opt/airflow/dags/ETL_Raizen.py for tasks to queue
[2022-05-20 19:28:13,475] {logging_mixin.py:115} INFO - [2022-05-20 19:28:13,475] {dagbag.py:507} INFO - Filling up the DagBag from /opt/airflow/dags/ETL_Raizen.py
[2022-05-20 19:28:13,801] {logging_mixin.py:115} INFO - [2022-05-20 19:28:13,801] {dagbag.py:320} ERROR - Failed to import: /opt/airflow/dags/ETL_Raizen.py
Traceback (most recent call last):
  File "/home/airflow/.local/lib/python3.7/site-packages/airflow/models/dagbag.py", line 317, in parse
    loader.exec_module(new_module)
  File "<frozen importlib._bootstrap_external>", line 728, in exec_module
  File "<frozen importlib._bootstrap>", line 219, in _call_with_frames_removed
  File "/opt/airflow/dags/ETL_Raizen.py", line 107, in <module>
    with DAG('Teste_ETL_Raízen', start_date = datetime(2022,5,18),
NameError: name 'datetime' is not defined
[2022-05-20 19:28:13,801] {processor.py:653} WARNING - No viable dags retrieved from /opt/airflow/dags/ETL_Raizen.py
[2022-05-20 19:28:13,823] {processor.py:161} INFO - Processing /opt/airflow/dags/ETL_Raizen.py took 0.351 seconds
[2022-05-20 19:28:44,775] {processor.py:153} INFO - Started process (PID=3103) to work on /opt/airflow/dags/ETL_Raizen.py
[2022-05-20 19:28:44,783] {processor.py:641} INFO - Processing file /opt/airflow/dags/ETL_Raizen.py for tasks to queue
[2022-05-20 19:28:44,783] {logging_mixin.py:115} INFO - [2022-05-20 19:28:44,783] {dagbag.py:507} INFO - Filling up the DagBag from /opt/airflow/dags/ETL_Raizen.py
[2022-05-20 19:28:45,124] {logging_mixin.py:115} INFO - [2022-05-20 19:28:45,123] {dagbag.py:320} ERROR - Failed to import: /opt/airflow/dags/ETL_Raizen.py
Traceback (most recent call last):
  File "/home/airflow/.local/lib/python3.7/site-packages/airflow/models/dagbag.py", line 317, in parse
    loader.exec_module(new_module)
  File "<frozen importlib._bootstrap_external>", line 728, in exec_module
  File "<frozen importlib._bootstrap>", line 219, in _call_with_frames_removed
  File "/opt/airflow/dags/ETL_Raizen.py", line 107, in <module>
    with DAG('Teste_ETL_Raízen', start_date = datetime(2022,5,18),
NameError: name 'datetime' is not defined
[2022-05-20 19:28:45,124] {processor.py:653} WARNING - No viable dags retrieved from /opt/airflow/dags/ETL_Raizen.py
[2022-05-20 19:28:45,138] {processor.py:161} INFO - Processing /opt/airflow/dags/ETL_Raizen.py took 0.365 seconds
[2022-05-20 19:29:15,590] {processor.py:153} INFO - Started process (PID=3159) to work on /opt/airflow/dags/ETL_Raizen.py
[2022-05-20 19:29:15,598] {processor.py:641} INFO - Processing file /opt/airflow/dags/ETL_Raizen.py for tasks to queue
[2022-05-20 19:29:15,598] {logging_mixin.py:115} INFO - [2022-05-20 19:29:15,598] {dagbag.py:507} INFO - Filling up the DagBag from /opt/airflow/dags/ETL_Raizen.py
[2022-05-20 19:29:15,912] {logging_mixin.py:115} INFO - [2022-05-20 19:29:15,911] {dagbag.py:320} ERROR - Failed to import: /opt/airflow/dags/ETL_Raizen.py
Traceback (most recent call last):
  File "/home/airflow/.local/lib/python3.7/site-packages/airflow/models/dagbag.py", line 317, in parse
    loader.exec_module(new_module)
  File "<frozen importlib._bootstrap_external>", line 728, in exec_module
  File "<frozen importlib._bootstrap>", line 219, in _call_with_frames_removed
  File "/opt/airflow/dags/ETL_Raizen.py", line 107, in <module>
    with DAG('Teste_ETL_Raízen', start_date = datetime(2022,5,18),
NameError: name 'datetime' is not defined
[2022-05-20 19:29:15,912] {processor.py:653} WARNING - No viable dags retrieved from /opt/airflow/dags/ETL_Raizen.py
[2022-05-20 19:29:15,933] {processor.py:161} INFO - Processing /opt/airflow/dags/ETL_Raizen.py took 0.345 seconds
[2022-05-20 19:29:46,753] {processor.py:153} INFO - Started process (PID=3224) to work on /opt/airflow/dags/ETL_Raizen.py
[2022-05-20 19:29:46,761] {processor.py:641} INFO - Processing file /opt/airflow/dags/ETL_Raizen.py for tasks to queue
[2022-05-20 19:29:46,761] {logging_mixin.py:115} INFO - [2022-05-20 19:29:46,761] {dagbag.py:507} INFO - Filling up the DagBag from /opt/airflow/dags/ETL_Raizen.py
[2022-05-20 19:29:47,120] {logging_mixin.py:115} INFO - [2022-05-20 19:29:47,120] {dagbag.py:320} ERROR - Failed to import: /opt/airflow/dags/ETL_Raizen.py
Traceback (most recent call last):
  File "/home/airflow/.local/lib/python3.7/site-packages/airflow/models/dagbag.py", line 317, in parse
    loader.exec_module(new_module)
  File "<frozen importlib._bootstrap_external>", line 728, in exec_module
  File "<frozen importlib._bootstrap>", line 219, in _call_with_frames_removed
  File "/opt/airflow/dags/ETL_Raizen.py", line 107, in <module>
    with DAG('Teste_ETL_Raízen', start_date = datetime(2022,5,18),
NameError: name 'datetime' is not defined
[2022-05-20 19:29:47,120] {processor.py:653} WARNING - No viable dags retrieved from /opt/airflow/dags/ETL_Raizen.py
[2022-05-20 19:29:47,141] {processor.py:161} INFO - Processing /opt/airflow/dags/ETL_Raizen.py took 0.391 seconds
[2022-05-20 19:30:17,626] {processor.py:153} INFO - Started process (PID=3289) to work on /opt/airflow/dags/ETL_Raizen.py
[2022-05-20 19:30:17,634] {processor.py:641} INFO - Processing file /opt/airflow/dags/ETL_Raizen.py for tasks to queue
[2022-05-20 19:30:17,635] {logging_mixin.py:115} INFO - [2022-05-20 19:30:17,635] {dagbag.py:507} INFO - Filling up the DagBag from /opt/airflow/dags/ETL_Raizen.py
[2022-05-20 19:30:17,973] {logging_mixin.py:115} INFO - [2022-05-20 19:30:17,972] {dagbag.py:320} ERROR - Failed to import: /opt/airflow/dags/ETL_Raizen.py
Traceback (most recent call last):
  File "/home/airflow/.local/lib/python3.7/site-packages/airflow/models/dagbag.py", line 317, in parse
    loader.exec_module(new_module)
  File "<frozen importlib._bootstrap_external>", line 728, in exec_module
  File "<frozen importlib._bootstrap>", line 219, in _call_with_frames_removed
  File "/opt/airflow/dags/ETL_Raizen.py", line 107, in <module>
    with DAG('Teste_ETL_Raízen', start_date = datetime(2022,5,18),
NameError: name 'datetime' is not defined
[2022-05-20 19:30:17,973] {processor.py:653} WARNING - No viable dags retrieved from /opt/airflow/dags/ETL_Raizen.py
[2022-05-20 19:30:17,993] {processor.py:161} INFO - Processing /opt/airflow/dags/ETL_Raizen.py took 0.370 seconds
[2022-05-20 19:30:48,702] {processor.py:153} INFO - Started process (PID=3354) to work on /opt/airflow/dags/ETL_Raizen.py
[2022-05-20 19:30:48,710] {processor.py:641} INFO - Processing file /opt/airflow/dags/ETL_Raizen.py for tasks to queue
[2022-05-20 19:30:48,711] {logging_mixin.py:115} INFO - [2022-05-20 19:30:48,711] {dagbag.py:507} INFO - Filling up the DagBag from /opt/airflow/dags/ETL_Raizen.py
[2022-05-20 19:30:49,055] {logging_mixin.py:115} INFO - [2022-05-20 19:30:49,054] {dagbag.py:320} ERROR - Failed to import: /opt/airflow/dags/ETL_Raizen.py
Traceback (most recent call last):
  File "/home/airflow/.local/lib/python3.7/site-packages/airflow/models/dagbag.py", line 317, in parse
    loader.exec_module(new_module)
  File "<frozen importlib._bootstrap_external>", line 728, in exec_module
  File "<frozen importlib._bootstrap>", line 219, in _call_with_frames_removed
  File "/opt/airflow/dags/ETL_Raizen.py", line 107, in <module>
    with DAG('Teste_ETL_Raízen', start_date = datetime(2022,5,18),
NameError: name 'datetime' is not defined
[2022-05-20 19:30:49,055] {processor.py:653} WARNING - No viable dags retrieved from /opt/airflow/dags/ETL_Raizen.py
[2022-05-20 19:30:49,069] {processor.py:161} INFO - Processing /opt/airflow/dags/ETL_Raizen.py took 0.370 seconds
[2022-05-20 19:31:19,644] {processor.py:153} INFO - Started process (PID=3410) to work on /opt/airflow/dags/ETL_Raizen.py
[2022-05-20 19:31:19,652] {processor.py:641} INFO - Processing file /opt/airflow/dags/ETL_Raizen.py for tasks to queue
[2022-05-20 19:31:19,652] {logging_mixin.py:115} INFO - [2022-05-20 19:31:19,652] {dagbag.py:507} INFO - Filling up the DagBag from /opt/airflow/dags/ETL_Raizen.py
[2022-05-20 19:31:19,961] {logging_mixin.py:115} INFO - [2022-05-20 19:31:19,960] {dagbag.py:320} ERROR - Failed to import: /opt/airflow/dags/ETL_Raizen.py
Traceback (most recent call last):
  File "/home/airflow/.local/lib/python3.7/site-packages/airflow/models/dagbag.py", line 317, in parse
    loader.exec_module(new_module)
  File "<frozen importlib._bootstrap_external>", line 728, in exec_module
  File "<frozen importlib._bootstrap>", line 219, in _call_with_frames_removed
  File "/opt/airflow/dags/ETL_Raizen.py", line 107, in <module>
    with DAG('Teste_ETL_Raízen', start_date = datetime(2022,5,18),
NameError: name 'datetime' is not defined
[2022-05-20 19:31:19,961] {processor.py:653} WARNING - No viable dags retrieved from /opt/airflow/dags/ETL_Raizen.py
[2022-05-20 19:31:19,982] {processor.py:161} INFO - Processing /opt/airflow/dags/ETL_Raizen.py took 0.341 seconds
[2022-05-20 19:31:50,640] {processor.py:153} INFO - Started process (PID=3474) to work on /opt/airflow/dags/ETL_Raizen.py
[2022-05-20 19:31:50,649] {processor.py:641} INFO - Processing file /opt/airflow/dags/ETL_Raizen.py for tasks to queue
[2022-05-20 19:31:50,650] {logging_mixin.py:115} INFO - [2022-05-20 19:31:50,650] {dagbag.py:507} INFO - Filling up the DagBag from /opt/airflow/dags/ETL_Raizen.py
[2022-05-20 19:31:50,981] {logging_mixin.py:115} INFO - [2022-05-20 19:31:50,981] {dagbag.py:320} ERROR - Failed to import: /opt/airflow/dags/ETL_Raizen.py
Traceback (most recent call last):
  File "/home/airflow/.local/lib/python3.7/site-packages/airflow/models/dagbag.py", line 317, in parse
    loader.exec_module(new_module)
  File "<frozen importlib._bootstrap_external>", line 728, in exec_module
  File "<frozen importlib._bootstrap>", line 219, in _call_with_frames_removed
  File "/opt/airflow/dags/ETL_Raizen.py", line 107, in <module>
    with DAG('Teste_ETL_Raízen', start_date = datetime(2022,5,18),
NameError: name 'datetime' is not defined
[2022-05-20 19:31:50,981] {processor.py:653} WARNING - No viable dags retrieved from /opt/airflow/dags/ETL_Raizen.py
[2022-05-20 19:31:51,003] {processor.py:161} INFO - Processing /opt/airflow/dags/ETL_Raizen.py took 0.365 seconds
[2022-05-20 19:32:21,432] {processor.py:153} INFO - Started process (PID=3539) to work on /opt/airflow/dags/ETL_Raizen.py
[2022-05-20 19:32:21,440] {processor.py:641} INFO - Processing file /opt/airflow/dags/ETL_Raizen.py for tasks to queue
[2022-05-20 19:32:21,440] {logging_mixin.py:115} INFO - [2022-05-20 19:32:21,440] {dagbag.py:507} INFO - Filling up the DagBag from /opt/airflow/dags/ETL_Raizen.py
[2022-05-20 19:32:21,773] {logging_mixin.py:115} INFO - [2022-05-20 19:32:21,773] {dagbag.py:320} ERROR - Failed to import: /opt/airflow/dags/ETL_Raizen.py
Traceback (most recent call last):
  File "/home/airflow/.local/lib/python3.7/site-packages/airflow/models/dagbag.py", line 317, in parse
    loader.exec_module(new_module)
  File "<frozen importlib._bootstrap_external>", line 728, in exec_module
  File "<frozen importlib._bootstrap>", line 219, in _call_with_frames_removed
  File "/opt/airflow/dags/ETL_Raizen.py", line 107, in <module>
    with DAG('Teste_ETL_Raízen', start_date = datetime(2022,5,18),
NameError: name 'datetime' is not defined
[2022-05-20 19:32:21,773] {processor.py:653} WARNING - No viable dags retrieved from /opt/airflow/dags/ETL_Raizen.py
[2022-05-20 19:32:21,798] {processor.py:161} INFO - Processing /opt/airflow/dags/ETL_Raizen.py took 0.368 seconds
[2022-05-20 19:32:52,260] {processor.py:153} INFO - Started process (PID=3604) to work on /opt/airflow/dags/ETL_Raizen.py
[2022-05-20 19:32:52,268] {processor.py:641} INFO - Processing file /opt/airflow/dags/ETL_Raizen.py for tasks to queue
[2022-05-20 19:32:52,268] {logging_mixin.py:115} INFO - [2022-05-20 19:32:52,268] {dagbag.py:507} INFO - Filling up the DagBag from /opt/airflow/dags/ETL_Raizen.py
[2022-05-20 19:32:52,570] {logging_mixin.py:115} INFO - [2022-05-20 19:32:52,570] {dagbag.py:320} ERROR - Failed to import: /opt/airflow/dags/ETL_Raizen.py
Traceback (most recent call last):
  File "/home/airflow/.local/lib/python3.7/site-packages/airflow/models/dagbag.py", line 317, in parse
    loader.exec_module(new_module)
  File "<frozen importlib._bootstrap_external>", line 728, in exec_module
  File "<frozen importlib._bootstrap>", line 219, in _call_with_frames_removed
  File "/opt/airflow/dags/ETL_Raizen.py", line 107, in <module>
    with DAG('Teste_ETL_Raízen', start_date = datetime(2022,5,18),
NameError: name 'datetime' is not defined
[2022-05-20 19:32:52,570] {processor.py:653} WARNING - No viable dags retrieved from /opt/airflow/dags/ETL_Raizen.py
[2022-05-20 19:32:52,594] {processor.py:161} INFO - Processing /opt/airflow/dags/ETL_Raizen.py took 0.336 seconds
[2022-05-20 19:33:23,249] {processor.py:153} INFO - Started process (PID=3660) to work on /opt/airflow/dags/ETL_Raizen.py
[2022-05-20 19:33:23,257] {processor.py:641} INFO - Processing file /opt/airflow/dags/ETL_Raizen.py for tasks to queue
[2022-05-20 19:33:23,257] {logging_mixin.py:115} INFO - [2022-05-20 19:33:23,257] {dagbag.py:507} INFO - Filling up the DagBag from /opt/airflow/dags/ETL_Raizen.py
[2022-05-20 19:33:23,589] {logging_mixin.py:115} INFO - [2022-05-20 19:33:23,588] {dagbag.py:320} ERROR - Failed to import: /opt/airflow/dags/ETL_Raizen.py
Traceback (most recent call last):
  File "/home/airflow/.local/lib/python3.7/site-packages/airflow/models/dagbag.py", line 317, in parse
    loader.exec_module(new_module)
  File "<frozen importlib._bootstrap_external>", line 728, in exec_module
  File "<frozen importlib._bootstrap>", line 219, in _call_with_frames_removed
  File "/opt/airflow/dags/ETL_Raizen.py", line 107, in <module>
    with DAG('Teste_ETL_Raízen', start_date = datetime(2022,5,18),
NameError: name 'datetime' is not defined
[2022-05-20 19:33:23,589] {processor.py:653} WARNING - No viable dags retrieved from /opt/airflow/dags/ETL_Raizen.py
[2022-05-20 19:33:23,610] {processor.py:161} INFO - Processing /opt/airflow/dags/ETL_Raizen.py took 0.363 seconds
[2022-05-20 19:33:53,808] {processor.py:153} INFO - Started process (PID=3725) to work on /opt/airflow/dags/ETL_Raizen.py
[2022-05-20 19:33:53,816] {processor.py:641} INFO - Processing file /opt/airflow/dags/ETL_Raizen.py for tasks to queue
[2022-05-20 19:33:53,816] {logging_mixin.py:115} INFO - [2022-05-20 19:33:53,816] {dagbag.py:507} INFO - Filling up the DagBag from /opt/airflow/dags/ETL_Raizen.py
[2022-05-20 19:33:54,042] {logging_mixin.py:115} INFO - [2022-05-20 19:33:54,041] {dagbag.py:320} ERROR - Failed to import: /opt/airflow/dags/ETL_Raizen.py
Traceback (most recent call last):
  File "/home/airflow/.local/lib/python3.7/site-packages/airflow/models/dagbag.py", line 317, in parse
    loader.exec_module(new_module)
  File "<frozen importlib._bootstrap_external>", line 728, in exec_module
  File "<frozen importlib._bootstrap>", line 219, in _call_with_frames_removed
  File "/opt/airflow/dags/ETL_Raizen.py", line 107, in <module>
    with DAG('Teste_ETL_Raízen', start_date = datetime(2022,5,18),
NameError: name 'datetime' is not defined
[2022-05-20 19:33:54,042] {processor.py:653} WARNING - No viable dags retrieved from /opt/airflow/dags/ETL_Raizen.py
[2022-05-20 19:33:54,068] {processor.py:161} INFO - Processing /opt/airflow/dags/ETL_Raizen.py took 0.262 seconds
[2022-05-20 19:34:24,795] {processor.py:153} INFO - Started process (PID=3791) to work on /opt/airflow/dags/ETL_Raizen.py
[2022-05-20 19:34:24,804] {processor.py:641} INFO - Processing file /opt/airflow/dags/ETL_Raizen.py for tasks to queue
[2022-05-20 19:34:24,805] {logging_mixin.py:115} INFO - [2022-05-20 19:34:24,805] {dagbag.py:507} INFO - Filling up the DagBag from /opt/airflow/dags/ETL_Raizen.py
[2022-05-20 19:34:25,054] {logging_mixin.py:115} INFO - [2022-05-20 19:34:25,053] {dagbag.py:320} ERROR - Failed to import: /opt/airflow/dags/ETL_Raizen.py
Traceback (most recent call last):
  File "/home/airflow/.local/lib/python3.7/site-packages/airflow/models/dagbag.py", line 317, in parse
    loader.exec_module(new_module)
  File "<frozen importlib._bootstrap_external>", line 728, in exec_module
  File "<frozen importlib._bootstrap>", line 219, in _call_with_frames_removed
  File "/opt/airflow/dags/ETL_Raizen.py", line 107, in <module>
    with DAG('Teste_ETL_Raízen', start_date = datetime(2022,5,18),
NameError: name 'datetime' is not defined
[2022-05-20 19:34:25,054] {processor.py:653} WARNING - No viable dags retrieved from /opt/airflow/dags/ETL_Raizen.py
[2022-05-20 19:34:25,080] {processor.py:161} INFO - Processing /opt/airflow/dags/ETL_Raizen.py took 0.287 seconds
[2022-05-20 19:34:55,935] {processor.py:153} INFO - Started process (PID=3847) to work on /opt/airflow/dags/ETL_Raizen.py
[2022-05-20 19:34:55,941] {processor.py:641} INFO - Processing file /opt/airflow/dags/ETL_Raizen.py for tasks to queue
[2022-05-20 19:34:55,942] {logging_mixin.py:115} INFO - [2022-05-20 19:34:55,942] {dagbag.py:507} INFO - Filling up the DagBag from /opt/airflow/dags/ETL_Raizen.py
[2022-05-20 19:34:56,175] {logging_mixin.py:115} INFO - [2022-05-20 19:34:56,174] {dagbag.py:320} ERROR - Failed to import: /opt/airflow/dags/ETL_Raizen.py
Traceback (most recent call last):
  File "/home/airflow/.local/lib/python3.7/site-packages/airflow/models/dagbag.py", line 317, in parse
    loader.exec_module(new_module)
  File "<frozen importlib._bootstrap_external>", line 728, in exec_module
  File "<frozen importlib._bootstrap>", line 219, in _call_with_frames_removed
  File "/opt/airflow/dags/ETL_Raizen.py", line 107, in <module>
    with DAG('Teste_ETL_Raízen', start_date = datetime(2022,5,18),
NameError: name 'datetime' is not defined
[2022-05-20 19:34:56,175] {processor.py:653} WARNING - No viable dags retrieved from /opt/airflow/dags/ETL_Raizen.py
[2022-05-20 19:34:56,198] {processor.py:161} INFO - Processing /opt/airflow/dags/ETL_Raizen.py took 0.265 seconds
[2022-05-20 19:35:26,861] {processor.py:153} INFO - Started process (PID=3912) to work on /opt/airflow/dags/ETL_Raizen.py
[2022-05-20 19:35:26,861] {processor.py:641} INFO - Processing file /opt/airflow/dags/ETL_Raizen.py for tasks to queue
[2022-05-20 19:35:26,861] {logging_mixin.py:115} INFO - [2022-05-20 19:35:26,861] {dagbag.py:507} INFO - Filling up the DagBag from /opt/airflow/dags/ETL_Raizen.py
[2022-05-20 19:35:27,068] {logging_mixin.py:115} INFO - [2022-05-20 19:35:27,067] {dagbag.py:320} ERROR - Failed to import: /opt/airflow/dags/ETL_Raizen.py
Traceback (most recent call last):
  File "/home/airflow/.local/lib/python3.7/site-packages/airflow/models/dagbag.py", line 317, in parse
    loader.exec_module(new_module)
  File "<frozen importlib._bootstrap_external>", line 728, in exec_module
  File "<frozen importlib._bootstrap>", line 219, in _call_with_frames_removed
  File "/opt/airflow/dags/ETL_Raizen.py", line 107, in <module>
    with DAG('Teste_ETL_Raízen', start_date = datetime(2022,5,18),
NameError: name 'datetime' is not defined
[2022-05-20 19:35:27,068] {processor.py:653} WARNING - No viable dags retrieved from /opt/airflow/dags/ETL_Raizen.py
[2022-05-20 19:35:27,091] {processor.py:161} INFO - Processing /opt/airflow/dags/ETL_Raizen.py took 0.232 seconds
[2022-05-20 19:35:57,675] {processor.py:153} INFO - Started process (PID=3976) to work on /opt/airflow/dags/ETL_Raizen.py
[2022-05-20 19:35:57,683] {processor.py:641} INFO - Processing file /opt/airflow/dags/ETL_Raizen.py for tasks to queue
[2022-05-20 19:35:57,684] {logging_mixin.py:115} INFO - [2022-05-20 19:35:57,684] {dagbag.py:507} INFO - Filling up the DagBag from /opt/airflow/dags/ETL_Raizen.py
[2022-05-20 19:35:57,896] {logging_mixin.py:115} INFO - [2022-05-20 19:35:57,895] {dagbag.py:320} ERROR - Failed to import: /opt/airflow/dags/ETL_Raizen.py
Traceback (most recent call last):
  File "/home/airflow/.local/lib/python3.7/site-packages/airflow/models/dagbag.py", line 317, in parse
    loader.exec_module(new_module)
  File "<frozen importlib._bootstrap_external>", line 728, in exec_module
  File "<frozen importlib._bootstrap>", line 219, in _call_with_frames_removed
  File "/opt/airflow/dags/ETL_Raizen.py", line 107, in <module>
    with DAG('Teste_ETL_Raízen', start_date = datetime(2022,5,18),
NameError: name 'datetime' is not defined
[2022-05-20 19:35:57,896] {processor.py:653} WARNING - No viable dags retrieved from /opt/airflow/dags/ETL_Raizen.py
[2022-05-20 19:35:57,919] {processor.py:161} INFO - Processing /opt/airflow/dags/ETL_Raizen.py took 0.247 seconds
[2022-05-20 19:36:28,578] {processor.py:153} INFO - Started process (PID=4041) to work on /opt/airflow/dags/ETL_Raizen.py
[2022-05-20 19:36:28,586] {processor.py:641} INFO - Processing file /opt/airflow/dags/ETL_Raizen.py for tasks to queue
[2022-05-20 19:36:28,586] {logging_mixin.py:115} INFO - [2022-05-20 19:36:28,586] {dagbag.py:507} INFO - Filling up the DagBag from /opt/airflow/dags/ETL_Raizen.py
[2022-05-20 19:36:28,799] {logging_mixin.py:115} INFO - [2022-05-20 19:36:28,798] {dagbag.py:320} ERROR - Failed to import: /opt/airflow/dags/ETL_Raizen.py
Traceback (most recent call last):
  File "/home/airflow/.local/lib/python3.7/site-packages/airflow/models/dagbag.py", line 317, in parse
    loader.exec_module(new_module)
  File "<frozen importlib._bootstrap_external>", line 728, in exec_module
  File "<frozen importlib._bootstrap>", line 219, in _call_with_frames_removed
  File "/opt/airflow/dags/ETL_Raizen.py", line 107, in <module>
    with DAG('Teste_ETL_Raízen', start_date = datetime(2022,5,18),
NameError: name 'datetime' is not defined
[2022-05-20 19:36:28,799] {processor.py:653} WARNING - No viable dags retrieved from /opt/airflow/dags/ETL_Raizen.py
[2022-05-20 19:36:28,825] {processor.py:161} INFO - Processing /opt/airflow/dags/ETL_Raizen.py took 0.249 seconds
[2022-05-20 19:36:59,392] {processor.py:153} INFO - Started process (PID=4097) to work on /opt/airflow/dags/ETL_Raizen.py
[2022-05-20 19:36:59,400] {processor.py:641} INFO - Processing file /opt/airflow/dags/ETL_Raizen.py for tasks to queue
[2022-05-20 19:36:59,401] {logging_mixin.py:115} INFO - [2022-05-20 19:36:59,400] {dagbag.py:507} INFO - Filling up the DagBag from /opt/airflow/dags/ETL_Raizen.py
[2022-05-20 19:36:59,634] {logging_mixin.py:115} INFO - [2022-05-20 19:36:59,633] {dagbag.py:320} ERROR - Failed to import: /opt/airflow/dags/ETL_Raizen.py
Traceback (most recent call last):
  File "/home/airflow/.local/lib/python3.7/site-packages/airflow/models/dagbag.py", line 317, in parse
    loader.exec_module(new_module)
  File "<frozen importlib._bootstrap_external>", line 728, in exec_module
  File "<frozen importlib._bootstrap>", line 219, in _call_with_frames_removed
  File "/opt/airflow/dags/ETL_Raizen.py", line 107, in <module>
    with DAG('Teste_ETL_Raízen', start_date = datetime(2022,5,18),
NameError: name 'datetime' is not defined
[2022-05-20 19:36:59,634] {processor.py:653} WARNING - No viable dags retrieved from /opt/airflow/dags/ETL_Raizen.py
[2022-05-20 19:36:59,657] {processor.py:161} INFO - Processing /opt/airflow/dags/ETL_Raizen.py took 0.267 seconds
[2022-05-20 19:37:30,303] {processor.py:153} INFO - Started process (PID=4161) to work on /opt/airflow/dags/ETL_Raizen.py
[2022-05-20 19:37:30,304] {processor.py:641} INFO - Processing file /opt/airflow/dags/ETL_Raizen.py for tasks to queue
[2022-05-20 19:37:30,304] {logging_mixin.py:115} INFO - [2022-05-20 19:37:30,304] {dagbag.py:507} INFO - Filling up the DagBag from /opt/airflow/dags/ETL_Raizen.py
[2022-05-20 19:37:30,537] {logging_mixin.py:115} INFO - [2022-05-20 19:37:30,536] {dagbag.py:320} ERROR - Failed to import: /opt/airflow/dags/ETL_Raizen.py
Traceback (most recent call last):
  File "/home/airflow/.local/lib/python3.7/site-packages/airflow/models/dagbag.py", line 317, in parse
    loader.exec_module(new_module)
  File "<frozen importlib._bootstrap_external>", line 728, in exec_module
  File "<frozen importlib._bootstrap>", line 219, in _call_with_frames_removed
  File "/opt/airflow/dags/ETL_Raizen.py", line 107, in <module>
    with DAG('Teste_ETL_Raízen', start_date = datetime(2022,5,18),
NameError: name 'datetime' is not defined
[2022-05-20 19:37:30,538] {processor.py:653} WARNING - No viable dags retrieved from /opt/airflow/dags/ETL_Raizen.py
[2022-05-20 19:37:30,553] {processor.py:161} INFO - Processing /opt/airflow/dags/ETL_Raizen.py took 0.252 seconds
[2022-05-20 19:38:01,080] {processor.py:153} INFO - Started process (PID=4226) to work on /opt/airflow/dags/ETL_Raizen.py
[2022-05-20 19:38:01,081] {processor.py:641} INFO - Processing file /opt/airflow/dags/ETL_Raizen.py for tasks to queue
[2022-05-20 19:38:01,081] {logging_mixin.py:115} INFO - [2022-05-20 19:38:01,081] {dagbag.py:507} INFO - Filling up the DagBag from /opt/airflow/dags/ETL_Raizen.py
[2022-05-20 19:38:01,306] {logging_mixin.py:115} INFO - [2022-05-20 19:38:01,305] {dagbag.py:320} ERROR - Failed to import: /opt/airflow/dags/ETL_Raizen.py
Traceback (most recent call last):
  File "/home/airflow/.local/lib/python3.7/site-packages/airflow/models/dagbag.py", line 317, in parse
    loader.exec_module(new_module)
  File "<frozen importlib._bootstrap_external>", line 728, in exec_module
  File "<frozen importlib._bootstrap>", line 219, in _call_with_frames_removed
  File "/opt/airflow/dags/ETL_Raizen.py", line 107, in <module>
    with DAG('Teste_ETL_Raízen', start_date = datetime(2022,5,18),
NameError: name 'datetime' is not defined
[2022-05-20 19:38:01,306] {processor.py:653} WARNING - No viable dags retrieved from /opt/airflow/dags/ETL_Raizen.py
[2022-05-20 19:38:01,329] {processor.py:161} INFO - Processing /opt/airflow/dags/ETL_Raizen.py took 0.252 seconds
[2022-05-20 19:38:31,948] {processor.py:153} INFO - Started process (PID=4284) to work on /opt/airflow/dags/ETL_Raizen.py
[2022-05-20 19:38:31,956] {processor.py:641} INFO - Processing file /opt/airflow/dags/ETL_Raizen.py for tasks to queue
[2022-05-20 19:38:31,956] {logging_mixin.py:115} INFO - [2022-05-20 19:38:31,956] {dagbag.py:507} INFO - Filling up the DagBag from /opt/airflow/dags/ETL_Raizen.py
[2022-05-20 19:38:32,183] {logging_mixin.py:115} INFO - [2022-05-20 19:38:32,182] {dagbag.py:320} ERROR - Failed to import: /opt/airflow/dags/ETL_Raizen.py
Traceback (most recent call last):
  File "/home/airflow/.local/lib/python3.7/site-packages/airflow/models/dagbag.py", line 317, in parse
    loader.exec_module(new_module)
  File "<frozen importlib._bootstrap_external>", line 728, in exec_module
  File "<frozen importlib._bootstrap>", line 219, in _call_with_frames_removed
  File "/opt/airflow/dags/ETL_Raizen.py", line 107, in <module>
    with DAG('Teste_ETL_Raízen', start_date = datetime(2022,5,18),
NameError: name 'datetime' is not defined
[2022-05-20 19:38:32,183] {processor.py:653} WARNING - No viable dags retrieved from /opt/airflow/dags/ETL_Raizen.py
[2022-05-20 19:38:32,206] {processor.py:161} INFO - Processing /opt/airflow/dags/ETL_Raizen.py took 0.261 seconds
[2022-05-20 19:39:02,803] {processor.py:153} INFO - Started process (PID=4347) to work on /opt/airflow/dags/ETL_Raizen.py
[2022-05-20 19:39:02,811] {processor.py:641} INFO - Processing file /opt/airflow/dags/ETL_Raizen.py for tasks to queue
[2022-05-20 19:39:02,811] {logging_mixin.py:115} INFO - [2022-05-20 19:39:02,811] {dagbag.py:507} INFO - Filling up the DagBag from /opt/airflow/dags/ETL_Raizen.py
[2022-05-20 19:39:03,038] {logging_mixin.py:115} INFO - [2022-05-20 19:39:03,037] {dagbag.py:320} ERROR - Failed to import: /opt/airflow/dags/ETL_Raizen.py
Traceback (most recent call last):
  File "/home/airflow/.local/lib/python3.7/site-packages/airflow/models/dagbag.py", line 317, in parse
    loader.exec_module(new_module)
  File "<frozen importlib._bootstrap_external>", line 728, in exec_module
  File "<frozen importlib._bootstrap>", line 219, in _call_with_frames_removed
  File "/opt/airflow/dags/ETL_Raizen.py", line 107, in <module>
    with DAG('Teste_ETL_Raízen', start_date = datetime(2022,5,18),
NameError: name 'datetime' is not defined
[2022-05-20 19:39:03,038] {processor.py:653} WARNING - No viable dags retrieved from /opt/airflow/dags/ETL_Raizen.py
[2022-05-20 19:39:03,061] {processor.py:161} INFO - Processing /opt/airflow/dags/ETL_Raizen.py took 0.261 seconds
[2022-05-20 19:39:33,621] {processor.py:153} INFO - Started process (PID=4412) to work on /opt/airflow/dags/ETL_Raizen.py
[2022-05-20 19:39:33,629] {processor.py:641} INFO - Processing file /opt/airflow/dags/ETL_Raizen.py for tasks to queue
[2022-05-20 19:39:33,629] {logging_mixin.py:115} INFO - [2022-05-20 19:39:33,629] {dagbag.py:507} INFO - Filling up the DagBag from /opt/airflow/dags/ETL_Raizen.py
[2022-05-20 19:39:33,887] {logging_mixin.py:115} INFO - [2022-05-20 19:39:33,886] {dagbag.py:320} ERROR - Failed to import: /opt/airflow/dags/ETL_Raizen.py
Traceback (most recent call last):
  File "/home/airflow/.local/lib/python3.7/site-packages/airflow/models/dagbag.py", line 317, in parse
    loader.exec_module(new_module)
  File "<frozen importlib._bootstrap_external>", line 728, in exec_module
  File "<frozen importlib._bootstrap>", line 219, in _call_with_frames_removed
  File "/opt/airflow/dags/ETL_Raizen.py", line 107, in <module>
    with DAG('Teste_ETL_Raízen', start_date = datetime(2022,5,18),
NameError: name 'datetime' is not defined
[2022-05-20 19:39:33,888] {processor.py:653} WARNING - No viable dags retrieved from /opt/airflow/dags/ETL_Raizen.py
[2022-05-20 19:39:33,905] {processor.py:161} INFO - Processing /opt/airflow/dags/ETL_Raizen.py took 0.286 seconds
[2022-05-20 19:40:04,442] {processor.py:153} INFO - Started process (PID=4477) to work on /opt/airflow/dags/ETL_Raizen.py
[2022-05-20 19:40:04,450] {processor.py:641} INFO - Processing file /opt/airflow/dags/ETL_Raizen.py for tasks to queue
[2022-05-20 19:40:04,452] {logging_mixin.py:115} INFO - [2022-05-20 19:40:04,451] {dagbag.py:507} INFO - Filling up the DagBag from /opt/airflow/dags/ETL_Raizen.py
[2022-05-20 19:40:04,681] {logging_mixin.py:115} INFO - [2022-05-20 19:40:04,680] {dagbag.py:320} ERROR - Failed to import: /opt/airflow/dags/ETL_Raizen.py
Traceback (most recent call last):
  File "/home/airflow/.local/lib/python3.7/site-packages/airflow/models/dagbag.py", line 317, in parse
    loader.exec_module(new_module)
  File "<frozen importlib._bootstrap_external>", line 728, in exec_module
  File "<frozen importlib._bootstrap>", line 219, in _call_with_frames_removed
  File "/opt/airflow/dags/ETL_Raizen.py", line 107, in <module>
    with DAG('Teste_ETL_Raízen', start_date = datetime(2022,5,18),
NameError: name 'datetime' is not defined
[2022-05-20 19:40:04,681] {processor.py:653} WARNING - No viable dags retrieved from /opt/airflow/dags/ETL_Raizen.py
[2022-05-20 19:40:04,701] {processor.py:161} INFO - Processing /opt/airflow/dags/ETL_Raizen.py took 0.261 seconds
[2022-05-20 19:40:35,300] {processor.py:153} INFO - Started process (PID=4533) to work on /opt/airflow/dags/ETL_Raizen.py
[2022-05-20 19:40:35,308] {processor.py:641} INFO - Processing file /opt/airflow/dags/ETL_Raizen.py for tasks to queue
[2022-05-20 19:40:35,308] {logging_mixin.py:115} INFO - [2022-05-20 19:40:35,308] {dagbag.py:507} INFO - Filling up the DagBag from /opt/airflow/dags/ETL_Raizen.py
[2022-05-20 19:40:35,515] {logging_mixin.py:115} INFO - [2022-05-20 19:40:35,514] {dagbag.py:320} ERROR - Failed to import: /opt/airflow/dags/ETL_Raizen.py
Traceback (most recent call last):
  File "/home/airflow/.local/lib/python3.7/site-packages/airflow/models/dagbag.py", line 317, in parse
    loader.exec_module(new_module)
  File "<frozen importlib._bootstrap_external>", line 728, in exec_module
  File "<frozen importlib._bootstrap>", line 219, in _call_with_frames_removed
  File "/opt/airflow/dags/ETL_Raizen.py", line 107, in <module>
    with DAG('Teste_ETL_Raízen', start_date = datetime(2022,5,18),
NameError: name 'datetime' is not defined
[2022-05-20 19:40:35,515] {processor.py:653} WARNING - No viable dags retrieved from /opt/airflow/dags/ETL_Raizen.py
[2022-05-20 19:40:35,539] {processor.py:161} INFO - Processing /opt/airflow/dags/ETL_Raizen.py took 0.241 seconds
[2022-05-20 19:41:06,130] {processor.py:153} INFO - Started process (PID=4598) to work on /opt/airflow/dags/ETL_Raizen.py
[2022-05-20 19:41:06,138] {processor.py:641} INFO - Processing file /opt/airflow/dags/ETL_Raizen.py for tasks to queue
[2022-05-20 19:41:06,139] {logging_mixin.py:115} INFO - [2022-05-20 19:41:06,138] {dagbag.py:507} INFO - Filling up the DagBag from /opt/airflow/dags/ETL_Raizen.py
[2022-05-20 19:41:06,367] {logging_mixin.py:115} INFO - [2022-05-20 19:41:06,366] {dagbag.py:320} ERROR - Failed to import: /opt/airflow/dags/ETL_Raizen.py
Traceback (most recent call last):
  File "/home/airflow/.local/lib/python3.7/site-packages/airflow/models/dagbag.py", line 317, in parse
    loader.exec_module(new_module)
  File "<frozen importlib._bootstrap_external>", line 728, in exec_module
  File "<frozen importlib._bootstrap>", line 219, in _call_with_frames_removed
  File "/opt/airflow/dags/ETL_Raizen.py", line 107, in <module>
    with DAG('Teste_ETL_Raízen', start_date = datetime(2022,5,18),
NameError: name 'datetime' is not defined
[2022-05-20 19:41:06,367] {processor.py:653} WARNING - No viable dags retrieved from /opt/airflow/dags/ETL_Raizen.py
[2022-05-20 19:41:06,389] {processor.py:161} INFO - Processing /opt/airflow/dags/ETL_Raizen.py took 0.261 seconds
[2022-05-20 19:41:37,138] {processor.py:153} INFO - Started process (PID=4663) to work on /opt/airflow/dags/ETL_Raizen.py
[2022-05-20 19:41:37,139] {processor.py:641} INFO - Processing file /opt/airflow/dags/ETL_Raizen.py for tasks to queue
[2022-05-20 19:41:37,139] {logging_mixin.py:115} INFO - [2022-05-20 19:41:37,139] {dagbag.py:507} INFO - Filling up the DagBag from /opt/airflow/dags/ETL_Raizen.py
[2022-05-20 19:41:37,365] {logging_mixin.py:115} INFO - [2022-05-20 19:41:37,364] {dagbag.py:320} ERROR - Failed to import: /opt/airflow/dags/ETL_Raizen.py
Traceback (most recent call last):
  File "/home/airflow/.local/lib/python3.7/site-packages/airflow/models/dagbag.py", line 317, in parse
    loader.exec_module(new_module)
  File "<frozen importlib._bootstrap_external>", line 728, in exec_module
  File "<frozen importlib._bootstrap>", line 219, in _call_with_frames_removed
  File "/opt/airflow/dags/ETL_Raizen.py", line 107, in <module>
    with DAG('Teste_ETL_Raízen', start_date = datetime(2022,5,18),
NameError: name 'datetime' is not defined
[2022-05-20 19:41:37,366] {processor.py:653} WARNING - No viable dags retrieved from /opt/airflow/dags/ETL_Raizen.py
[2022-05-20 19:41:37,380] {processor.py:161} INFO - Processing /opt/airflow/dags/ETL_Raizen.py took 0.244 seconds
[2022-05-20 19:42:07,948] {processor.py:153} INFO - Started process (PID=4728) to work on /opt/airflow/dags/ETL_Raizen.py
[2022-05-20 19:42:07,956] {processor.py:641} INFO - Processing file /opt/airflow/dags/ETL_Raizen.py for tasks to queue
[2022-05-20 19:42:07,956] {logging_mixin.py:115} INFO - [2022-05-20 19:42:07,956] {dagbag.py:507} INFO - Filling up the DagBag from /opt/airflow/dags/ETL_Raizen.py
[2022-05-20 19:42:08,195] {logging_mixin.py:115} INFO - [2022-05-20 19:42:08,194] {dagbag.py:320} ERROR - Failed to import: /opt/airflow/dags/ETL_Raizen.py
Traceback (most recent call last):
  File "/home/airflow/.local/lib/python3.7/site-packages/airflow/models/dagbag.py", line 317, in parse
    loader.exec_module(new_module)
  File "<frozen importlib._bootstrap_external>", line 728, in exec_module
  File "<frozen importlib._bootstrap>", line 219, in _call_with_frames_removed
  File "/opt/airflow/dags/ETL_Raizen.py", line 107, in <module>
    with DAG('Teste_ETL_Raízen', start_date = datetime(2022,5,18),
NameError: name 'datetime' is not defined
[2022-05-20 19:42:08,195] {processor.py:653} WARNING - No viable dags retrieved from /opt/airflow/dags/ETL_Raizen.py
[2022-05-20 19:42:08,218] {processor.py:161} INFO - Processing /opt/airflow/dags/ETL_Raizen.py took 0.272 seconds
[2022-05-20 19:42:38,752] {processor.py:153} INFO - Started process (PID=4784) to work on /opt/airflow/dags/ETL_Raizen.py
[2022-05-20 19:42:38,760] {processor.py:641} INFO - Processing file /opt/airflow/dags/ETL_Raizen.py for tasks to queue
[2022-05-20 19:42:38,760] {logging_mixin.py:115} INFO - [2022-05-20 19:42:38,760] {dagbag.py:507} INFO - Filling up the DagBag from /opt/airflow/dags/ETL_Raizen.py
[2022-05-20 19:42:38,998] {logging_mixin.py:115} INFO - [2022-05-20 19:42:38,997] {dagbag.py:320} ERROR - Failed to import: /opt/airflow/dags/ETL_Raizen.py
Traceback (most recent call last):
  File "/home/airflow/.local/lib/python3.7/site-packages/airflow/models/dagbag.py", line 317, in parse
    loader.exec_module(new_module)
  File "<frozen importlib._bootstrap_external>", line 728, in exec_module
  File "<frozen importlib._bootstrap>", line 219, in _call_with_frames_removed
  File "/opt/airflow/dags/ETL_Raizen.py", line 107, in <module>
    with DAG('Teste_ETL_Raízen', start_date = datetime(2022,5,18),
NameError: name 'datetime' is not defined
[2022-05-20 19:42:38,998] {processor.py:653} WARNING - No viable dags retrieved from /opt/airflow/dags/ETL_Raizen.py
[2022-05-20 19:42:39,018] {processor.py:161} INFO - Processing /opt/airflow/dags/ETL_Raizen.py took 0.268 seconds
[2022-05-20 19:43:09,779] {processor.py:153} INFO - Started process (PID=4850) to work on /opt/airflow/dags/ETL_Raizen.py
[2022-05-20 19:43:09,788] {processor.py:641} INFO - Processing file /opt/airflow/dags/ETL_Raizen.py for tasks to queue
[2022-05-20 19:43:09,789] {logging_mixin.py:115} INFO - [2022-05-20 19:43:09,789] {dagbag.py:507} INFO - Filling up the DagBag from /opt/airflow/dags/ETL_Raizen.py
[2022-05-20 19:43:10,028] {logging_mixin.py:115} INFO - [2022-05-20 19:43:10,027] {dagbag.py:320} ERROR - Failed to import: /opt/airflow/dags/ETL_Raizen.py
Traceback (most recent call last):
  File "/home/airflow/.local/lib/python3.7/site-packages/airflow/models/dagbag.py", line 317, in parse
    loader.exec_module(new_module)
  File "<frozen importlib._bootstrap_external>", line 728, in exec_module
  File "<frozen importlib._bootstrap>", line 219, in _call_with_frames_removed
  File "/opt/airflow/dags/ETL_Raizen.py", line 107, in <module>
    with DAG('Teste_ETL_Raízen', start_date = datetime(2022,5,18),
NameError: name 'datetime' is not defined
[2022-05-20 19:43:10,029] {processor.py:653} WARNING - No viable dags retrieved from /opt/airflow/dags/ETL_Raizen.py
[2022-05-20 19:43:10,064] {processor.py:161} INFO - Processing /opt/airflow/dags/ETL_Raizen.py took 0.289 seconds
[2022-05-20 19:43:40,614] {processor.py:153} INFO - Started process (PID=4915) to work on /opt/airflow/dags/ETL_Raizen.py
[2022-05-20 19:43:40,614] {processor.py:641} INFO - Processing file /opt/airflow/dags/ETL_Raizen.py for tasks to queue
[2022-05-20 19:43:40,614] {logging_mixin.py:115} INFO - [2022-05-20 19:43:40,614] {dagbag.py:507} INFO - Filling up the DagBag from /opt/airflow/dags/ETL_Raizen.py
[2022-05-20 19:43:40,836] {logging_mixin.py:115} INFO - [2022-05-20 19:43:40,835] {dagbag.py:320} ERROR - Failed to import: /opt/airflow/dags/ETL_Raizen.py
Traceback (most recent call last):
  File "/home/airflow/.local/lib/python3.7/site-packages/airflow/models/dagbag.py", line 317, in parse
    loader.exec_module(new_module)
  File "<frozen importlib._bootstrap_external>", line 728, in exec_module
  File "<frozen importlib._bootstrap>", line 219, in _call_with_frames_removed
  File "/opt/airflow/dags/ETL_Raizen.py", line 107, in <module>
    with DAG('Teste_ETL_Raízen', start_date = datetime(2022,5,18),
NameError: name 'datetime' is not defined
[2022-05-20 19:43:40,836] {processor.py:653} WARNING - No viable dags retrieved from /opt/airflow/dags/ETL_Raizen.py
[2022-05-20 19:43:40,851] {processor.py:161} INFO - Processing /opt/airflow/dags/ETL_Raizen.py took 0.240 seconds
