[2022-05-19 03:19:56,371] {taskinstance.py:1159} INFO - Dependencies all met for <TaskInstance: Teste_ETL_Raízen.captura_conta_dados manual__2022-05-19T03:19:54.300030+00:00 [queued]>
[2022-05-19 03:19:56,381] {taskinstance.py:1159} INFO - Dependencies all met for <TaskInstance: Teste_ETL_Raízen.captura_conta_dados manual__2022-05-19T03:19:54.300030+00:00 [queued]>
[2022-05-19 03:19:56,382] {taskinstance.py:1356} INFO - 
--------------------------------------------------------------------------------
[2022-05-19 03:19:56,382] {taskinstance.py:1357} INFO - Starting attempt 1 of 1
[2022-05-19 03:19:56,383] {taskinstance.py:1358} INFO - 
--------------------------------------------------------------------------------
[2022-05-19 03:19:56,398] {taskinstance.py:1377} INFO - Executing <Task(PythonOperator): captura_conta_dados> on 2022-05-19 03:19:54.300030+00:00
[2022-05-19 03:19:56,404] {standard_task_runner.py:52} INFO - Started process 3147 to run task
[2022-05-19 03:19:56,407] {standard_task_runner.py:79} INFO - Running: ['***', 'tasks', 'run', 'Teste_ETL_Raízen', 'captura_conta_dados', 'manual__2022-05-19T03:19:54.300030+00:00', '--job-id', '6', '--raw', '--subdir', 'DAGS_FOLDER/ETL_Raizen.py', '--cfg-path', '/tmp/tmpckpmvplx', '--error-file', '/tmp/tmpz2k1a_00']
[2022-05-19 03:19:56,408] {standard_task_runner.py:80} INFO - Job 6: Subtask captura_conta_dados
[2022-05-19 03:19:56,469] {task_command.py:369} INFO - Running <TaskInstance: Teste_ETL_Raízen.captura_conta_dados manual__2022-05-19T03:19:54.300030+00:00 [running]> on host c8caf9da75ac
[2022-05-19 03:19:56,545] {taskinstance.py:1571} INFO - Exporting the following env vars:
AIRFLOW_CTX_DAG_OWNER=***
AIRFLOW_CTX_DAG_ID=Teste_ETL_Raízen
AIRFLOW_CTX_TASK_ID=captura_conta_dados
AIRFLOW_CTX_EXECUTION_DATE=2022-05-19T03:19:54.300030+00:00
AIRFLOW_CTX_TRY_NUMBER=1
AIRFLOW_CTX_DAG_RUN_ID=manual__2022-05-19T03:19:54.300030+00:00
[2022-05-19 03:19:56,547] {taskinstance.py:1889} ERROR - Task failed with exception
Traceback (most recent call last):
  File "/home/airflow/.local/lib/python3.7/site-packages/airflow/operators/python.py", line 171, in execute
    return_value = self.execute_callable()
  File "/home/airflow/.local/lib/python3.7/site-packages/airflow/operators/python.py", line 189, in execute_callable
    return self.python_callable(*self.op_args, **self.op_kwargs)
  File "/opt/airflow/dags/ETL_Raizen.py", line 11, in captura_conta_dados
    response = request.get(url)
NameError: name 'request' is not defined
[2022-05-19 03:19:56,561] {taskinstance.py:1400} INFO - Marking task as FAILED. dag_id=Teste_ETL_Raízen, task_id=captura_conta_dados, execution_date=20220519T031954, start_date=20220519T031956, end_date=20220519T031956
[2022-05-19 03:19:56,573] {standard_task_runner.py:97} ERROR - Failed to execute job 6 for task captura_conta_dados (name 'request' is not defined; 3147)
[2022-05-19 03:19:56,581] {local_task_job.py:156} INFO - Task exited with return code 1
[2022-05-19 03:19:56,625] {local_task_job.py:273} INFO - 0 downstream tasks scheduled from follow-on schedule check
